Workbook

Sheet Summary
B2: Summary Report - BC RAEDA 1A | H2: Summary Report - BC RAEDA 1B
B3: Type | C3: No of Trucks Released from WH | D3: Bags | E3: Net | F3: Gross | H3: Type | I3: No of Trucks Released from WH | J3: Bags | K3: Net | L3: Gross | N3: DESTINATION | O3: NET | P3: GROSS
B4: Pumpi - 1A | C4: 53 | D4: =+'BL-1A-Pumpi'!H3 -> 1499 | E4: =+'BL-1A-Pumpi'!I3 -> 1871.603 | F4: =+'BL-1A-Pumpi'!J3 -> 1978.453 | H4: Pumpi - 1B | I4: 54 | J4: 1500 | K4: 1875 | L4: 1879.778 | N4: PUMPI | O4: =E4+K4 -> 3746.603 | P4: =F4+L4 -> 3858.231
B5: Likasi - 1A | C5: 72 | D5: =+'BL-1A-Likasi'!H3 -> 2024 | E5: =+'BL-1A-Likasi'!I3 -> 2527.175 | F5: =+'BL-1A-Likasi'!J3 -> 2798.254 | H5: Likasi - 1B | I5: 49 | J5: 1365 | K5: 1711.323 | L5: 1734.737 | N5: LIKASI | O5: =E5+K5 -> 4238.498 | P5: =F5+L5 -> 4532.991
B6: Kolwezi - 1A | C6: 17 | D6: =+'BL-1A-Kolwezi'!H3 -> 476 | E6: =+'BL-1A-Kolwezi'!I3 -> 595 | F6: =+'BL-1A-Kolwezi'!J3 -> 596.216 | H6: Kolwezi - 1B | I6: 40 | J6: 1125 | K6: 1407.5 | L6: 1411.448 | N6: KOLWEZI | O6: =E6+J6 -> 1720 | P6: =F6+L6 -> 2007.664
B7: Total uplifted | C7: =SUM(C4:C6) -> 142 | D7: =SUM(D4:D6) -> 3999 | E7: =SUM(E4:E6) -> 4993.778 | F7: =SUM(F4:F6) -> 5372.923 | H7: Total uplifted | I7: =SUM(I4:I6) -> 143 | J7: =SUM(J4:J6) -> 3990 | K7: =SUM(K4:K6) -> 4993.823 | L7: =SUM(L4:L6) -> 5025.963 | N7: TOTAL UPLIFTED | O7: =SUM(O4:O6) -> 9705.101 | P7: =SUM(P4:P6) -> 10398.886
B8: As per BoL -1A | C8: 144 | D8: =+Master!H1 -> 3992 | E8: =+Master!I1 -> 4990 | F8: =+Master!J1 -> 5003.991 | H8: As per BoL -1A | J8: 3991 | K8: =4988750/1000 -> 4988.75 | L8: =5002736.75/1000 -> 5002.7368 | N8: AS PER BL | O8: =E8+K8 -> 9978.75 | P8: =F8+L8 -> 10006.728
B9: Stock in WH | D9: =+D8-D7 -> -7 | E9: =+E8-E7 -> -3.778 | F9: =+F8-F7 -> -368.932 | J9: =J8-J7 -> 1 | K9: =K8-K7 -> -5.073 | L9: =L8-L7 -> -23.22625 | N9: DIFFERENCE | O9: =O8-O7 -> 273.649 | P9: =P8-P7 -> -392.15825
C11: Difference | D11: =+D7-Master!H3 -> -4018 | E11: =+E7-Master!I3 -> -5025.073 | F11: =+F7-Master!J3 -> -5057.356
B14: BC RAEDA
B15: BL | C15: waiting to release Dar | D15: In -Transit TZ | E15: At Tunduma | F15: At Nakonde | G15: In -Transit Zambia | H15: At K-lesa Borders | I15: In transit DRC | J15: Waiting to Offload | K15: Offloaded | L15: Total
B16: 1A Likasi | C16: 0 | D16: 0 | E16: 0 | F16: 0 | G16: 0 | H16: 0 | I16: 0 | J16: 0 | K16: 72 | L16: =SUM(C16:K16) -> 72
B17: 1A kolwezi | C17: 0 | D17: 0 | E17: 0 | F17: 0 | G17: 0 | H17: 0 | I17: 0 | J17: 0 | K17: 18 | L17: =SUM(C17:K17) -> 18
B18: 1A Pumpi | C18: 0 | D18: 0 | E18: 0 | F18: 0 | G18: 0 | H18: 0 | I18: 1 | J18: 0 | K18: 52 | L18: =SUM(C18:K18) -> 53
B19: 1B Likasi | C19: 0 | D19: 0 | E19: 0 | F19: 0 | G19: 2 | H19: 13 | I19: 0 | J19: 0 | K19: 34 | L19: =SUM(C19:K19) -> 49
B20: 1B Kolwezi | C20: 0 | D20: 0 | E20: 2 | F20: 1 | G20: 9 | H20: 28 | I20: 0 | J20: 0 | K20: 0 | L20: =SUM(C20:K20) -> 40
B21: 1B Pumpi | C21: 0 | D21: 10 | E21: 1 | F21: 4 | G21: 14 | H21: 18 | I21: 0 | J21: 0 | K21: 7 | L21: =SUM(C21:K21) -> 54
L22: =SUM(L16:L21) -> 286

Sheet Master
A1: DAILY TRACKING REPORT - FORWARDING | E1: =TODAY() -> 46045 | F1: BC RAEDA | G1: H-DAN | H1: 3992 | I1: 4990 | J1: 5003.991 | K1: =+H1-H3 -> -4025 | L1: =+I1-I3 -> -5028.851 | M1: =+J1-J3 -> -5426.288 | N1: GT OCEAN TRANSPORTATION LIMITED | T1: GT OCEAN TRANSPORTATION LIMITED | AB1: GT OCEAN TRANSPORTATION LIMITED | AN1: Total Amount
A2: 序号 | B2: 提单号 | C2: 卡车牌号 | D2: 拖车牌号 | E2: 司机姓名 | F2: 目的地 | G2: 当前位置 | H2: 吨袋/bags | I2: 净重/N.W. | J2: 毛重/G.W. | L2: 文件接收 | M2: 船司 | N2: 船名 | O2: 预计抵港 | P2: 实际靠泊 | Q2: 船司放行 | R2: 装运时间 | S2: 起运时间 | T2: 到达TUNDUMA | U2: NAKONDE出发 | V2: 到达卡松ZAMBIA | W2: 卡松ZAMBIA出发 | X2: 到达卡松DRC | Y2: 卡松出发DRC | AB2: 到达目的地 | AC2: 卸货时间 | AD2: 备注 | AE2: Border Delays | AI2: =SUM(AI213:AI272) -> 11400 | AJ2: Offloading Delays | AN2: =SUM(AN213:AN289) -> 3400 | AO2: =SUM(AO213:AO289) -> 2000 | AP2: =SUM(AI2:AO2) -> 16800
A3: No. | B3: B/L | C3: TRUCK NUMBER | D3: TRAILER NUMBER | E3: DRIVER NAME | F3: FINAL DESTINATION | G3: TRUCK POSITION | H3: =SUM(H4:H289) -> 8017 | I3: =SUM(I4:I289)/1000 -> 10018.851 | J3: =SUM(J4:J289)/1000 -> 10430.279 | K3: HDAN | L3: DOCUMENTS RECEIVED | M3: SHIPPING LINE | N3: VESSEL | O3: ETA | P3: ATB | Q3: LINE RELEASE | R3: DATE LOADED | S3: DISPATCH DATE | T3: ARRIVED TUNDUMA BORDER | U3: DEPARTED NAKONDE | V3: K-LESA ZAMBIA ARRIVED | W3: K-LESA ZAMBIA DEPARTED | X3: K-LESA DRC ARRIVED | Y3: K-LESA DRC DEPARTED | Z3: L-MBASHI ARRIVED | AA3: DEPARTED L-MBASHI | AB3: ARRIVED DESTINATION | AC3: OFFLOADED | AD3: COMMENTS | AE3: Border Days | AF3: Free days | AG3: Chargable Days | AH3: Chargable Rate | AI3: Border Delays Amt | AJ3: Offloading Days | AK3: Free days | AL3: Chargable Days | AM3: Chargable Rate | AN3: Offloading Delays Amt | AO3: Parking Charges Amount | AP3: TOTAL
A4: =ROW()-3 -> 1 | B4: 1B | C4: T922EDD | D4: T501EDC-T719EPL | E4: OMARY HAMISI SALUM | F4: PUMPI | G4: CFS VINGUNGUTI | H4: 28 | I4: 35000 | J4: 35098 | K4: AN-HDAN | L4: 45890 | M4: ESL | N4: BC Raeda | O4: 45881 | P4: 45907 | Q4: 45892 | R4: 46040 | AD4: Loaded waitig release | AE4: =MAX(0,Y4-X4) -> 0 | AF4: 7 | AG4: =MAX(0,AE4-AF4) -> 0 | AH4: 200 | AI4: =MAX(0,AG4*AH4) -> 0 | AJ4: =MAX(0,AC4-AB4) -> 0 | AK4: 2 | AL4: =MAX(0,AJ4-AK4) -> 0 | AM4: 200 | AN4: =MAX(0,AL4*AM4) -> 0 | AP4: =AO4+AN4+AI4 -> 0
A5: =ROW()-3 -> 2 | B5: 1B | C5: T497DMH | D5: T541BWU-T275ELA | E5: ABDULRAZAK ATHUMAN HABIBU | F5: PUMPI | G5: CFS VINGUNGUTI | H5: 28 | I5: 35000 | J5: 35098 | K5: AN-HDAN | L5: 45890 | M5: ESL | N5: BC Raeda | O5: 45881 | P5: 45907 | Q5: 45892 | R5: 46040 | AD5: Loaded waitig release | AE5: =MAX(0,Y5-X5) -> 0 | AF5: 7 | AG5: =MAX(0,AE5-AF5) -> 0 | AH5: 200 | AI5: =MAX(0,AG5*AH5) -> 0 | AJ5: =MAX(0,AC5-AB5) -> 0 | AK5: 2 | AL5: =MAX(0,AJ5-AK5) -> 0 | AM5: 200 | AN5: =MAX(0,AL5*AM5) -> 0 | AP5: =AO5+AN5+AI5 -> 0
A6: =ROW()-3 -> 3 | B6: 1B | C6: T868CJS | D6: T955ASG-T395DSM | E6: RAMADHANI MOHAMED LIBONGE | F6: PUMPI | G6: CFS VINGUNGUTI | H6: 28 | I6: 35000 | J6: 35098 | K6: AN-HDAN | L6: 45890 | M6: ESL | N6: BC Raeda | O6: 45881 | P6: 45907 | Q6: 45892 | R6: 46040 | AD6: Loaded waitig release | AE6: =MAX(0,Y6-X6) -> 0 | AF6: 7 | AG6: =MAX(0,AE6-AF6) -> 0 | AH6: 200 | AI6: =MAX(0,AG6*AH6) -> 0 | AJ6: =MAX(0,AC6-AB6) -> 0 | AK6: 2 | AL6: =MAX(0,AJ6-AK6) -> 0 | AM6: 200 | AN6: =MAX(0,AL6*AM6) -> 0 | AP6: =AO6+AN6+AI6 -> 0
A7: =ROW()-3 -> 4 | B7: 1B | C7: T679CJT | D7: T925CTU-T216EMM | E7: EZEKIEL SAMWEL SHILAYE | F7: PUMPI | G7: CFS VINGUNGUTI | H7: 28 | I7: 35000 | J7: 35098 | K7: AN-HDAN | L7: 45890 | M7: ESL | N7: BC Raeda | O7: 45881 | P7: 45907 | Q7: 45892 | R7: 46040 | AD7: Loaded waitig release | AE7: =MAX(0,Y7-X7) -> 0 | AF7: 7 | AG7: =MAX(0,AE7-AF7) -> 0 | AH7: 200 | AI7: =MAX(0,AG7*AH7) -> 0 | AJ7: =MAX(0,AC7-AB7) -> 0 | AK7: 2 | AL7: =MAX(0,AJ7-AK7) -> 0 | AM7: 200 | AN7: =MAX(0,AL7*AM7) -> 0 | AP7: =AO7+AN7+AI7 -> 0
A8: =ROW()-3 -> 5 | B8: 1B | C8: T944DEY | D8: T383DGN | E8: FRANK PAULO CHIWANGO | F8: PUMPI | G8: CFS VINGUNGUTI | H8: 29 | I8: 36250 | J8: 36352 | K8: AN-HDAN | L8: 45890 | M8: ESL | N8: BC Raeda | O8: 45881 | P8: 45907 | Q8: 45892 | R8: 46040 | AD8: Loaded waitig release | AE8: =MAX(0,Y8-X8) -> 0 | AF8: 7 | AG8: =MAX(0,AE8-AF8) -> 0 | AH8: 200 | AI8: =MAX(0,AG8*AH8) -> 0 | AJ8: =MAX(0,AC8-AB8) -> 0 | AK8: 2 | AL8: =MAX(0,AJ8-AK8) -> 0 | AM8: 200 | AN8: =MAX(0,AL8*AM8) -> 0 | AP8: =AO8+AN8+AI8 -> 0
A9: =ROW()-3 -> 6 | B9: 1B | C9: T797CCY | D9: T169AHE-T693EFH | E9: HAMIS SHAIBU NGAYELA | F9: PUMPI | G9: CFS VINGUNGUTI | H9: 28 | I9: 35000 | J9: 35098 | K9: AN-HDAN | L9: 45890 | M9: ESL | N9: BC Raeda | O9: 45881 | P9: 45907 | Q9: 45892 | R9: 46040 | AD9: Loaded waitig release | AE9: =MAX(0,Y9-X9) -> 0 | AF9: 7 | AG9: =MAX(0,AE9-AF9) -> 0 | AH9: 200 | AI9: =MAX(0,AG9*AH9) -> 0 | AJ9: =MAX(0,AC9-AB9) -> 0 | AK9: 2 | AL9: =MAX(0,AJ9-AK9) -> 0 | AM9: 200 | AN9: =MAX(0,AL9*AM9) -> 0 | AP9: =AO9+AN9+AI9 -> 0
A10: =ROW()-3 -> 7 | B10: 1B | C10: T699DRY | D10: T207DSK | E10: CHARLES LUCAS MTENGULE | F10: PUMPI | G10: CFS VINGUNGUTI | H10: 29 | I10: 36250 | J10: 36352 | K10: AN-HDAN | L10: 45890 | M10: ESL | N10: BC Raeda | O10: 45881 | P10: 45907 | Q10: 45892 | R10: 46040 | AD10: Loaded waitig release | AE10: =MAX(0,Y10-X10) -> 0 | AF10: 7 | AG10: =MAX(0,AE10-AF10) -> 0 | AH10: 200 | AI10: =MAX(0,AG10*AH10) -> 0 | AJ10: =MAX(0,AC10-AB10) -> 0 | AK10: 2 | AL10: =MAX(0,AJ10-AK10) -> 0 | AM10: 200 | AN10: =MAX(0,AL10*AM10) -> 0 | AP10: =AO10+AN10+AI10 -> 0
A11: =ROW()-3 -> 8 | B11: 1B | C11: T648CJT | D11: T499DAA | E11: MELKION NICHOLAUS NTOGHA | F11: PUMPI | G11: CFS VINGUNGUTI | H11: 24 | I11: 30000 | J11: 30084 | K11: AN-HDAN | L11: 45890 | M11: ESL | N11: BC Raeda | O11: 45881 | P11: 45907 | Q11: 45892 | R11: 46040 | AD11: Loaded waitig release | AE11: =MAX(0,Y11-X11) -> 0 | AF11: 7 | AG11: =MAX(0,AE11-AF11) -> 0 | AH11: 200 | AI11: =MAX(0,AG11*AH11) -> 0 | AJ11: =MAX(0,AC11-AB11) -> 0 | AK11: 2 | AL11: =MAX(0,AJ11-AK11) -> 0 | AM11: 200 | AN11: =MAX(0,AL11*AM11) -> 0 | AP11: =AO11+AN11+AI11 -> 0
A12: =ROW()-3 -> 9 | B12: 1B | C12: T192EES | D12: T714CWH | E12: ANDREW GEORGE KAUNDE | F12: PUMPI | G12: CFS VINGUNGUTI | H12: 24 | I12: 30000 | J12: 30084 | K12: AN-HDAN | L12: 45890 | M12: ESL | N12: BC Raeda | O12: 45881 | P12: 45907 | Q12: 45892 | R12: 46040 | AD12: Loaded waitig release | AE12: =MAX(0,Y12-X12) -> 0 | AF12: 7 | AG12: =MAX(0,AE12-AF12) -> 0 | AH12: 200 | AI12: =MAX(0,AG12*AH12) -> 0 | AJ12: =MAX(0,AC12-AB12) -> 0 | AK12: 2 | AL12: =MAX(0,AJ12-AK12) -> 0 | AM12: 200 | AN12: =MAX(0,AL12*AM12) -> 0 | AP12: =AO12+AN12+AI12 -> 0
A13: =ROW()-3 -> 10 | B13: 1B | C13: T383DZH | D13: T466CBM-T287EMP | E13: MOHAMED MUSSA MOHAMED | F13: PUMPI | G13: CFS VINGUNGUTI | H13: 28 | I13: 35000 | J13: 35098 | K13: AN-HDAN | L13: 45890 | M13: ESL | N13: BC Raeda | O13: 45881 | P13: 45907 | Q13: 45892 | R13: 46038 | AD13: Loaded waitig release
A14: =ROW()-3 -> 11 | B14: 1B | C14: T885ECV | D14: T496DCA | E14: SHABANI SAID MBONDE | F14: PUMPI | G14: CFS VINGUNGUTI | H14: 29 | I14: 36250 | J14: 36352 | K14: AN-HDAN | L14: 45890 | M14: ESL | N14: BC Raeda | O14: 45881 | P14: 45907 | Q14: 45892 | R14: 46038 | AD14: Loaded waitig release
A15: =ROW()-3 -> 12 | B15: 1B | C15: T232DNF | D15: T569CTF-T566DTR | E15: BASHIRI WAZIRI MFINANGA | F15: PUMPI | G15: CFS VINGUNGUTI | H15: 28 | I15: 35000 | J15: 35098 | K15: AN-HDAN | L15: 45890 | M15: ESL | N15: BC Raeda | O15: 45881 | P15: 45907 | Q15: 45892 | R15: 46038 | AD15: Loaded waitig release
A16: =ROW()-3 -> 13 | B16: 1B | C16: T825ENP | D16: T292EFX-T296EFX | E16: AHIMIDIWE JACKSON MASAKI | F16: PUMPI | G16: CFS VINGUNGUTI | H16: 28 | I16: 35000 | J16: 35098 | K16: AN-HDAN | L16: 45890 | M16: ESL | N16: BC Raeda | O16: 45881 | P16: 45907 | Q16: 45892 | R16: 46038 | AD16: Loaded waitig release
A17: =ROW()-3 -> 14 | B17: 1B | C17: T651BZY | D17: T654AVR-T512EFH | E17: OMARY JUMA MSUMARI | F17: PUMPI | G17: CFS VINGUNGUTI | H17: 28 | I17: 35000 | J17: 35098 | K17: AN-HDAN | L17: 45890 | M17: ESL | N17: BC Raeda | O17: 45881 | P17: 45907 | Q17: 45892 | R17: 46038 | AD17: Loaded waitig release
A18: =ROW()-3 -> 15 | B18: 1B | C18: T660BZH | D18: T648AVR-T380DSM | E18: WILLIAM PAULO MINJA | F18: PUMPI | G18: CFS VINGUNGUTI | H18: 28 | I18: 35000 | J18: 35098 | K18: AN-HDAN | L18: 45890 | M18: ESL | N18: BC Raeda | O18: 45881 | P18: 45907 | Q18: 45892 | R18: 46038 | AD18: Loaded waitig release
A19: =ROW()-3 -> 16 | B19: 1B | C19: T330DWZ | D19: T247ARR-T318DUD | E19: MASAMA G BARNABA | F19: PUMPI | G19: CFS VINGUNGUTI | H19: 28 | I19: 35000 | J19: 35098 | K19: AN-HDAN | L19: 45890 | M19: ESL | N19: BC Raeda | O19: 45881 | P19: 45907 | Q19: 45892 | R19: 46038 | AD19: Loaded waitig release
A20: =ROW()-3 -> 17 | B20: 1B | C20: T223EES | D20: T186DED-T575DTR | E20: PAULO JENGO PAULO | F20: PUMPI | G20: CFS VINGUNGUTI | H20: 28 | I20: 35000 | J20: 35098 | K20: AN-HDAN | L20: 45890 | M20: ESL | N20: BC Raeda | O20: 45881 | P20: 45907 | Q20: 45892 | R20: 46036 | S20: 46038 | AD20: In Transit
A21: =ROW()-3 -> 18 | B21: 1B | C21: T318CFY | D21: T200BED-T670EFH | E21: AHMED MOHAMED CHALACHALA | F21: PUMPI | G21: CFS VINGUNGUTI | H21: 28 | I21: 35000 | J21: 35098 | K21: AN-HDAN | L21: 45890 | M21: ESL | N21: BC Raeda | O21: 45881 | P21: 45907 | Q21: 45892 | R21: 46031 | AD21: Loaded waitig release | AE21: =MAX(0,Y21-X21) -> 0 | AF21: 7 | AG21: =MAX(0,AE21-AF21) -> 0 | AH21: 200 | AI21: =MAX(0,AG21*AH21) -> 0 | AJ21: =MAX(0,AC21-AB21) -> 0 | AK21: 2 | AL21: =MAX(0,AJ21-AK21) -> 0 | AM21: 200 | AN21: =MAX(0,AL21*AM21) -> 0 | AP21: =AO21+AN21+AI21 -> 0
A22: =ROW()-3 -> 19 | B22: 1B | C22: T998DNE | D22: T724AHL-T372DSM | E22: MIRAJI JABIRY KAMONGO | F22: PUMPI | G22: CFS VINGUNGUTI | H22: 28 | I22: 35000 | J22: 35098 | K22: AN-HDAN | L22: 45890 | M22: ESL | N22: BC Raeda | O22: 45881 | P22: 45907 | Q22: 45892 | R22: 46031 | AD22: Loaded waitig release | AE22: =MAX(0,Y22-X22) -> 0 | AF22: 7 | AG22: =MAX(0,AE22-AF22) -> 0 | AH22: 200 | AI22: =MAX(0,AG22*AH22) -> 0 | AJ22: =MAX(0,AC22-AB22) -> 0 | AK22: 2 | AL22: =MAX(0,AJ22-AK22) -> 0 | AM22: 200 | AN22: =MAX(0,AL22*AM22) -> 0 | AP22: =AO22+AN22+AI22 -> 0
A23: =ROW()-3 -> 20 | B23: 1B | C23: T711DMS | D23: T239DQD-T518DQD | E23: RICHARD IPOLE MWAKATUMBULA | F23: PUMPI | G23: CFS VINGUNGUTI | H23: 27 | I23: 33750 | J23: 33845 | K23: AN-HDAN | L23: 45890 | M23: ESL | N23: BC Raeda | O23: 45881 | P23: 45907 | Q23: 45892 | R23: 46032 | AD23: Loaded waitig release | AE23: =MAX(0,Y23-X23) -> 0 | AF23: 7 | AG23: =MAX(0,AE23-AF23) -> 0 | AH23: 200 | AI23: =MAX(0,AG23*AH23) -> 0 | AJ23: =MAX(0,AC23-AB23) -> 0 | AK23: 2 | AL23: =MAX(0,AJ23-AK23) -> 0 | AM23: 200 | AN23: =MAX(0,AL23*AM23) -> 0 | AP23: =AO23+AN23+AI23 -> 0
A24: =ROW()-3 -> 21 | B24: 1B | C24: T830ENP | D24: T413EFX-T192EFX | E24: OMARY MOHAMED ALLY | F24: PUMPI | G24: CFS VINGUNGUTI | H24: 28 | I24: 35000 | J24: 35098 | K24: AN-HDAN | L24: 45890 | M24: ESL | N24: BC Raeda | O24: 45881 | P24: 45907 | Q24: 45892 | R24: 46036 | AD24: Loaded waitig release | AE24: =MAX(0,Y24-X24) -> 0 | AF24: 7 | AG24: =MAX(0,AE24-AF24) -> 0 | AH24: 200 | AI24: =MAX(0,AG24*AH24) -> 0 | AJ24: =MAX(0,AC24-AB24) -> 0 | AK24: 2 | AL24: =MAX(0,AJ24-AK24) -> 0 | AM24: 200 | AN24: =MAX(0,AL24*AM24) -> 0 | AP24: =AO24+AN24+AI24 -> 0
A25: =ROW()-3 -> 22 | B25: 1B | C25: T149EES | D25: T105EHW-T195EMP | E25: SHABANI JUMA KAPELA | F25: PUMPI | G25: CFS VINGUNGUTI | H25: 28 | I25: 35000 | J25: 35098 | K25: AN-HDAN | L25: 45890 | M25: ESL | N25: BC Raeda | O25: 45881 | P25: 45907 | Q25: 45892 | R25: 46036 | AD25: Loaded waitig release | AE25: =MAX(0,Y25-X25) -> 0 | AF25: 7 | AG25: =MAX(0,AE25-AF25) -> 0 | AH25: 200 | AI25: =MAX(0,AG25*AH25) -> 0 | AJ25: =MAX(0,AC25-AB25) -> 0 | AK25: 2 | AL25: =MAX(0,AJ25-AK25) -> 0 | AM25: 200 | AN25: =MAX(0,AL25*AM25) -> 0 | AP25: =AO25+AN25+AI25 -> 0
A26: =ROW()-3 -> 23 | B26: 1B | C26: T873CQL | D26: T178DED-T578DTR | E26: CHILE JACKOBU MAHENGE | F26: PUMPI | G26: CFS VINGUNGUTI | H26: 28 | I26: 35000 | J26: 35098 | K26: AN-HDAN | L26: 45890 | M26: ESL | N26: BC Raeda | O26: 45881 | P26: 45907 | Q26: 45892 | R26: 46036 | AD26: Loaded waitig release | AE26: =MAX(0,Y26-X26) -> 0 | AF26: 7 | AG26: =MAX(0,AE26-AF26) -> 0 | AH26: 200 | AI26: =MAX(0,AG26*AH26) -> 0 | AJ26: =MAX(0,AC26-AB26) -> 0 | AK26: 2 | AL26: =MAX(0,AJ26-AK26) -> 0 | AM26: 200 | AN26: =MAX(0,AL26*AM26) -> 0 | AP26: =AO26+AN26+AI26 -> 0
A27: =ROW()-3 -> 24 | B27: 1B | C27: T879CQL | D27: T375CRT-T426EFH | E27: JOHN PAULO MZALIFU | F27: PUMPI | G27: CFS VINGUNGUTI | H27: 28 | I27: 35000 | J27: 35098 | K27: AN-HDAN | L27: 45890 | M27: ESL | N27: BC Raeda | O27: 45881 | P27: 45907 | Q27: 45892 | R27: 46036 | AD27: Loaded waitig release | AE27: =MAX(0,Y27-X27) -> 0 | AF27: 7 | AG27: =MAX(0,AE27-AF27) -> 0 | AH27: 200 | AI27: =MAX(0,AG27*AH27) -> 0 | AJ27: =MAX(0,AC27-AB27) -> 0 | AK27: 2 | AL27: =MAX(0,AJ27-AK27) -> 0 | AM27: 200 | AN27: =MAX(0,AL27*AM27) -> 0 | AP27: =AO27+AN27+AI27 -> 0
A28: =ROW()-3 -> 25 | B28: 1B | C28: T716DMS | D28: T270DQD-T507DQD | E28: DEOGRASIAS INYASI SHIO | F28: PUMPI | G28: CFS VINGUNGUTI | H28: 27 | I28: 33750 | J28: 33845 | K28: AN-HDAN | L28: 45890 | M28: ESL | N28: BC Raeda | O28: 45881 | P28: 45907 | Q28: 45892 | R28: 46036 | AD28: Loaded waitig release | AE28: =MAX(0,Y28-X28) -> 0 | AF28: 7 | AG28: =MAX(0,AE28-AF28) -> 0 | AH28: 200 | AI28: =MAX(0,AG28*AH28) -> 0 | AJ28: =MAX(0,AC28-AB28) -> 0 | AK28: 2 | AL28: =MAX(0,AJ28-AK28) -> 0 | AM28: 200 | AN28: =MAX(0,AL28*AM28) -> 0 | AP28: =AO28+AN28+AI28 -> 0
A29: =ROW()-3 -> 26 | B29: 1B | C29: T796DRY | D29: T205DSK | E29: HEMED SAID HEMED | F29: PUMPI | G29: CFS VINGUNGUTI | H29: 29 | I29: 36250 | J29: 36352 | K29: AN-HDAN | L29: 45890 | M29: ESL | N29: BC Raeda | O29: 45881 | P29: 45907 | Q29: 45892 | R29: 46036 | AD29: Loaded waitig release | AE29: =MAX(0,Y29-X29) -> 0 | AF29: 7 | AG29: =MAX(0,AE29-AF29) -> 0 | AH29: 200 | AI29: =MAX(0,AG29*AH29) -> 0 | AJ29: =MAX(0,AC29-AB29) -> 0 | AK29: 2 | AL29: =MAX(0,AJ29-AK29) -> 0 | AM29: 200 | AN29: =MAX(0,AL29*AM29) -> 0 | AP29: =AO29+AN29+AI29 -> 0
A30: =ROW()-3 -> 27 | B30: 1B | C30: T331DWZ | D30: T203DEG-T987DWJ | E30: KENETH AMON LULENGA | F30: PUMPI | G30: CFS VINGUNGUTI | H30: 28 | I30: 35000 | J30: 35098 | K30: AN-HDAN | L30: 45890 | M30: ESL | N30: BC Raeda | O30: 45881 | P30: 45907 | Q30: 45892 | R30: 46036 | AD30: Loaded waitig release | AE30: =MAX(0,Y30-X30) -> 0 | AF30: 7 | AG30: =MAX(0,AE30-AF30) -> 0 | AH30: 200 | AI30: =MAX(0,AG30*AH30) -> 0 | AJ30: =MAX(0,AC30-AB30) -> 0 | AK30: 2 | AL30: =MAX(0,AJ30-AK30) -> 0 | AM30: 200 | AN30: =MAX(0,AL30*AM30) -> 0 | AP30: =AO30+AN30+AI30 -> 0
A31: =ROW()-3 -> 28 | B31: 1B | C31: T321CFY | D31: T693BMY | E31: MASHAKA SALUM KIYOYA | F31: PUMPI | G31: CFS VINGUNGUTI | H31: 24 | I31: 30000 | J31: 30084 | K31: AN-HDAN | L31: 45890 | M31: ESL | N31: BC Raeda | O31: 45881 | P31: 45907 | Q31: 45892 | R31: 46036 | AD31: Loaded waitig release | AE31: =MAX(0,Y31-X31) -> 0 | AF31: 7 | AG31: =MAX(0,AE31-AF31) -> 0 | AH31: 200 | AI31: =MAX(0,AG31*AH31) -> 0 | AJ31: =MAX(0,AC31-AB31) -> 0 | AK31: 2 | AL31: =MAX(0,AJ31-AK31) -> 0 | AM31: 200 | AN31: =MAX(0,AL31*AM31) -> 0 | AP31: =AO31+AN31+AI31 -> 0
A32: =ROW()-3 -> 29 | B32: 1B | C32: T650DQF | D32: T272DQD-T513DQD | E32: ANTHONY ELIUD NGUMBI | F32: SICODEX KOLWEZI | G32: CFS VINGUNGUTI | H32: 28 | I32: 35000 | J32: 35098 | K32: AN-HDAN | L32: 45890 | M32: ESL | N32: BC Raeda | O32: 45881 | P32: 45907 | Q32: 45892 | AD32: Loaded waitig release | AE32: =MAX(0,Y32-X32) -> 0 | AF32: 7 | AG32: =MAX(0,AE32-AF32) -> 0 | AH32: 200 | AI32: =MAX(0,AG32*AH32) -> 0 | AJ32: =MAX(0,AC32-AB32) -> 0 | AK32: 2 | AL32: =MAX(0,AJ32-AK32) -> 0 | AM32: 200 | AN32: =MAX(0,AL32*AM32) -> 0 | AP32: =AO32+AN32+AI32 -> 0
A33: =ROW()-3 -> 30 | B33: 1B | C33: T872CQL | D33: T455CRA-T322DUD | E33: ABUBAKAR JUMA KIZENGA | F33: SICODEX KOLWEZI | G33: CFS VINGUNGUTI | H33: 28 | I33: 35000 | J33: 35098 | K33: AN-HDAN | L33: 45890 | M33: ESL | N33: BC Raeda | O33: 45881 | P33: 45907 | Q33: 45892 | AD33: Loaded waitig release | AE33: =MAX(0,Y33-X33) -> 0 | AF33: 7 | AG33: =MAX(0,AE33-AF33) -> 0 | AH33: 200 | AI33: =MAX(0,AG33*AH33) -> 0 | AJ33: =MAX(0,AC33-AB33) -> 0 | AK33: 2 | AL33: =MAX(0,AJ33-AK33) -> 0 | AM33: 200 | AN33: =MAX(0,AL33*AM33) -> 0 | AP33: =AO33+AN33+AI33 -> 0
A34: =ROW()-3 -> 31 | B34: 1B | C34: T658DQF | D34: T879DQF-T880DQF | E34: ALLY HUSSEIN KULILI | F34: SICODEX KOLWEZI | G34: CFS VINGUNGUTI | H34: 28 | I34: 35000 | J34: 35098 | K34: AN-HDAN | L34: 45890 | M34: ESL | N34: BC Raeda | O34: 45881 | P34: 45907 | Q34: 45892 | AD34: Loaded waitig release | AE34: =MAX(0,Y34-X34) -> 0 | AF34: 7 | AG34: =MAX(0,AE34-AF34) -> 0 | AH34: 200 | AI34: =MAX(0,AG34*AH34) -> 0 | AJ34: =MAX(0,AC34-AB34) -> 0 | AK34: 2 | AL34: =MAX(0,AJ34-AK34) -> 0 | AM34: 200 | AN34: =MAX(0,AL34*AM34) -> 0 | AP34: =AO34+AN34+AI34 -> 0
A35: =ROW()-3 -> 32 | B35: 1B | C35: T643DPW | D35: T211DEG | E35: HABIB ALLY MIANDANJE | F35: SICODEX KOLWEZI | G35: CFS VINGUNGUTI | H35: 25 | I35: 31250 | J35: 31338 | K35: AN-HDAN | L35: 45890 | M35: ESL | N35: BC Raeda | O35: 45881 | P35: 45907 | Q35: 45892 | AD35: Loaded waitig release | AE35: =MAX(0,Y35-X35) -> 0 | AF35: 7 | AG35: =MAX(0,AE35-AF35) -> 0 | AH35: 200 | AI35: =MAX(0,AG35*AH35) -> 0 | AJ35: =MAX(0,AC35-AB35) -> 0 | AK35: 2 | AL35: =MAX(0,AJ35-AK35) -> 0 | AM35: 200 | AN35: =MAX(0,AL35*AM35) -> 0 | AP35: =AO35+AN35+AI35 -> 0
A36: =ROW()-3 -> 33 | B36: 1B | C36: T903ECV | D36: T357EGE | E36: WILIADI LUKUSYILA MWAKYOMA | F36: SICODEX KOLWEZI | G36: CFS VINGUNGUTI | H36: 29 | I36: 36250 | J36: 36352 | K36: AN-HDAN | L36: 45890 | M36: ESL | N36: BC Raeda | O36: 45881 | P36: 45907 | Q36: 45892 | AD36: Loaded waitig release | AE36: =MAX(0,Y36-X36) -> 0 | AF36: 7 | AG36: =MAX(0,AE36-AF36) -> 0 | AH36: 200 | AI36: =MAX(0,AG36*AH36) -> 0 | AJ36: =MAX(0,AC36-AB36) -> 0 | AK36: 2 | AL36: =MAX(0,AJ36-AK36) -> 0 | AM36: 200 | AN36: =MAX(0,AL36*AM36) -> 0 | AP36: =AO36+AN36+AI36 -> 0
A37: =ROW()-3 -> 34 | B37: 1B | C37: T461DZH | D37: T503AUU-T245EMP | E37: DEOGRATIAS TADEUS TARIMO | F37: SICODEX KOLWEZI | G37: CFS VINGUNGUTI | H37: 28 | I37: 35000 | J37: 35098 | K37: AN-HDAN | L37: 45890 | M37: ESL | N37: BC Raeda | O37: 45881 | P37: 45907 | Q37: 45892 | R37: 46031 | AD37: Loaded waitig release | AE37: =MAX(0,Y37-X37) -> 0 | AF37: 7 | AG37: =MAX(0,AE37-AF37) -> 0 | AH37: 200 | AI37: =MAX(0,AG37*AH37) -> 0 | AJ37: =MAX(0,AC37-AB37) -> 0 | AK37: 2 | AL37: =MAX(0,AJ37-AK37) -> 0 | AM37: 200 | AN37: =MAX(0,AL37*AM37) -> 0 | AP37: =AO37+AN37+AI37 -> 0
A38: =ROW()-3 -> 35 | B38: 1B | C38: T658BVB | D38: T109APA-T524EFH | E38: THOBIAS NICOLAUS ANDREA | F38: SICODEX KOLWEZI | G38: CFS VINGUNGUTI | H38: 28 | I38: 35000 | J38: 35098 | K38: AN-HDAN | L38: 45890 | M38: ESL | N38: BC Raeda | O38: 45881 | P38: 45907 | Q38: 45892 | R38: 46031 | AD38: Loaded waitig release | AE38: =MAX(0,Y38-X38) -> 0 | AF38: 7 | AG38: =MAX(0,AE38-AF38) -> 0 | AH38: 200 | AI38: =MAX(0,AG38*AH38) -> 0 | AJ38: =MAX(0,AC38-AB38) -> 0 | AK38: 2 | AL38: =MAX(0,AJ38-AK38) -> 0 | AM38: 200 | AN38: =MAX(0,AL38*AM38) -> 0 | AP38: =AO38+AN38+AI38 -> 0
A39: =ROW()-3 -> 36 | B39: 1B | C39: T106DMZ | D39: T634DRM-T640DRM | E39: TWALIB JOSEPH CHUGA | F39: SICODEX KOLWEZI | G39: CFS VINGUNGUTI | H39: 28 | I39: 35000 | J39: 35098 | K39: AN-HDAN | L39: 45890 | M39: ESL | N39: BC Raeda | O39: 45881 | P39: 45907 | Q39: 45892 | R39: 46031 | AD39: Loaded waitig release | AE39: =MAX(0,Y39-X39) -> 0 | AF39: 7 | AG39: =MAX(0,AE39-AF39) -> 0 | AH39: 200 | AI39: =MAX(0,AG39*AH39) -> 0 | AJ39: =MAX(0,AC39-AB39) -> 0 | AK39: 2 | AL39: =MAX(0,AJ39-AK39) -> 0 | AM39: 200 | AN39: =MAX(0,AL39*AM39) -> 0 | AP39: =AO39+AN39+AI39 -> 0
A40: =ROW()-3 -> 37 | B40: 1B | C40: T334EFR | D40: T415EFX-T195EFX | E40: ZUBERI SAID ZUBERI | F40: SICODEX KOLWEZI | G40: CFS VINGUNGUTI | H40: 28 | I40: 35000 | J40: 35098 | K40: AN-HDAN | L40: 45890 | M40: ESL | N40: BC Raeda | O40: 45881 | P40: 45907 | Q40: 45892 | R40: 46031 | AD40: Loaded waitig release | AE40: =MAX(0,Y40-X40) -> 0 | AF40: 7 | AG40: =MAX(0,AE40-AF40) -> 0 | AH40: 200 | AI40: =MAX(0,AG40*AH40) -> 0 | AJ40: =MAX(0,AC40-AB40) -> 0 | AK40: 2 | AL40: =MAX(0,AJ40-AK40) -> 0 | AM40: 200 | AN40: =MAX(0,AL40*AM40) -> 0 | AP40: =AO40+AN40+AI40 -> 0
...

Sheet BL-1A-Pumpi
A1: DAILY TRACKING REPORT - FORWARDING | E1: =TODAY() -> 46045 | F1: BC RAEDA | G1: H-DAN | H1: 3992 | I1: 4990 | J1: 5003.991 | M1: GT OCEAN TRANSPORTATION LIMITED | T1: GT OCEAN TRANSPORTATION LIMITED | AB1: GT OCEAN TRANSPORTATION LIMITED | AN1: Total Amount
A2: 序号 | B2: 提单号 | C2: 卡车牌号 | D2: 拖车牌号 | E2: 司机姓名 | F2: 目的地 | G2: 当前位置 | H2: 吨袋/bags | I2: 净重/N.W. | J2: 毛重/G.W. | L2: 文件接收 | M2: 船司 | N2: 船名 | O2: 预计抵港 | P2: 实际靠泊 | Q2: 船司放行 | R2: 装运时间 | S2: 起运时间 | T2: 到达TUNDUMA | U2: NAKONDE出发 | V2: 到达卡松ZAMBIA | W2: 卡松ZAMBIA出发 | X2: 到达卡松DRC | Y2: 卡松出发DRC | AB2: 到达目的地 | AC2: 卸货时间 | AD2: 备注 | AE2: Border Delays | AI2: =SUM(AI38:AI56) -> 0 | AJ2: Offloading Delays | AN2: =SUM(AN38:AN56) -> 0 | AO2: =SUM(AO38:AO56) -> 0 | AP2: =SUM(AI2:AO2) -> 0
A3: No. | B3: B/L No. | C3: TRUCK NUMBER | D3: TRAILER NUMBER | E3: DRIVER NAME | F3: FINAL DESTINATION | G3: TRUCK POSITION | H3: =SUM(H4:H56) -> 1499 | I3: =SUM(I4:I56)/1000 -> 1871.603 | J3: =SUM(J4:J56)/1000 -> 1978.453 | K3: HDAN | L3: DOCUMENTS RECEIVED | M3: SHIPPING LINE | N3: VESSEL | O3: ETA | P3: ATB | Q3: LINE RELEASE | R3: DATE LOADED | S3: DISPATCH DATE | T3: ARRIVED TUNDUMA BORDER | U3: DEPARTED NAKONDE | V3: K-LESA ZAMBIA ARRIVED | W3: K-LESA ZAMBIA DEPARTED | X3: K-LESA DRC ARRIVED | Y3: K-LESA DRC DEPARTED | Z3: L-MBASHI ARRIVED | AA3: DEPARTED L-MBASHI | AB3: ARRIVED DESTINATION | AC3: OFFLOADED | AD3: COMMENTS | AE3: Border Days | AF3: Free days | AG3: Chargable Days | AH3: Chargable Rate | AI3: Border Delays Amt | AJ3: Offloading Days | AK3: Free days | AL3: Chargable Days | AM3: Chargable Rate | AN3: Offloading Delays Amt | AO3: Parking Charges Amount | AP3: TOTAL
A4: =ROW()-3 -> 1 | B4: 1A | C4: T327CFY | D4: T411BJE-T538EFH | E4: STEVEN LUCAS MBANGA | F4: PUMPI | G4: FUNGURUME DRC | H4: 28 | I4: 35000 | J4: 35070 | K4: AN-HDAN | L4: 45890 | M4: ESL | N4: BC Raeda | O4: 45881 | P4: 45907 | Q4: 45892 | R4: 45990 | S4: 45992 | T4: 46013 | U4: 46015 | V4: 46029 | W4: 46029 | X4: 46029 | Y4: 46036 | Z4: 46037 | AA4: 46037 | AD4: In Transit | AE4: =MAX(0,Y4-X4) -> 7 | AF4: 7 | AG4: =MAX(0,AE4-AF4) -> 0 | AH4: 200 | AI4: =MAX(0,AG4*AH4) -> 0 | AJ4: =MAX(0,AC4-AB4) -> 0 | AK4: 2 | AL4: =MAX(0,AJ4-AK4) -> 0 | AM4: 200 | AN4: =MAX(0,AL4*AM4) -> 0 | AP4: =AO4+AN4+AI4 -> 0
A5: =ROW()-3 -> 2 | B5: 1A | C5: T940DEY | D5: T320DGN | E5: SAID JUMA NASSOR | F5: PUMPI | G5: OFFLOADED | H5: 29 | I5: 36250 | J5: 36323 | K5: AN-HDAN | L5: 45890 | M5: ESL | N5: BC Raeda | O5: 45881 | P5: 45907 | Q5: 45892 | R5: 45992 | S5: 45995 | T5: 46007 | U5: 46013 | V5: 46017 | W5: 46017 | X5: 46017 | Y5: 46022 | Z5: 46023 | AA5: 46023 | AB5: 46023 | AC5: 46024 | AD5: COMPLETED | AE5: =MAX(0,Y5-X5) -> 5 | AF5: 7 | AG5: =MAX(0,AE5-AF5) -> 0 | AH5: 200 | AI5: =MAX(0,AG5*AH5) -> 0 | AJ5: =MAX(0,AC5-AB5) -> 1 | AK5: 2 | AL5: =MAX(0,AJ5-AK5) -> 0 | AM5: 200 | AN5: =MAX(0,AL5*AM5) -> 0 | AP5: =AO5+AN5+AI5 -> 0
A6: =ROW()-3 -> 3 | B6: 1A | C6: T892ECV | D6: T699CKC | E6: PAUL STEVEN SIANGA | F6: PUMPI | G6: OFFLOADED | H6: 28 | I6: 35000 | J6: 35070 | K6: AN-HDAN | L6: 45890 | M6: ESL | N6: BC Raeda | O6: 45881 | P6: 45907 | Q6: 45892 | R6: 45990 | S6: 45994 | T6: 45998 | U6: 46013 | V6: 46016 | W6: 46016 | X6: 46016 | Y6: 46021 | Z6: 46021 | AA6: 46021 | AB6: 46022 | AC6: 46024 | AD6: COMPLETED | AE6: =MAX(0,Y6-X6) -> 5 | AF6: 7 | AG6: =MAX(0,AE6-AF6) -> 0 | AH6: 200 | AI6: =MAX(0,AG6*AH6) -> 0 | AJ6: =MAX(0,AC6-AB6) -> 2 | AK6: 2 | AL6: =MAX(0,AJ6-AK6) -> 0 | AM6: 200 | AN6: =MAX(0,AL6*AM6) -> 0 | AO6: 0 | AP6: =AO6+AN6+AI6 -> 0
A7: =ROW()-3 -> 4 | B7: 1A | C7: T858DVK | D7: T536BWU | E7: ABDALLAH OMARY MNONJI | F7: PUMPI | G7: OFFLOADED | H7: 29 | I7: 36250 | J7: 36323 | K7: AN-HDAN | L7: 45890 | M7: ESL | N7: BC Raeda | O7: 45881 | P7: 45907 | Q7: 45892 | R7: 45992 | S7: 45995 | T7: 45999 | U7: 46006 | V7: 46011 | W7: 46011 | X7: 46011 | Y7: 46013 | Z7: 46014 | AA7: 46014 | AB7: 46014 | AC7: 46017 | AD7: COMPLETED | AE7: =MAX(0,Y7-X7) -> 2 | AF7: 7 | AG7: =MAX(0,AE7-AF7) -> 0 | AH7: 200 | AI7: =MAX(0,AG7*AH7) -> 0 | AJ7: =MAX(0,AC7-AB7) -> 3 | AK7: 2 | AL7: =MAX(0,AJ7-AK7) -> 1 | AM7: 200 | AN7: =MAX(0,AL7*AM7) -> 200 | AP7: =AO7+AN7+AI7 -> 200
A8: =ROW()-3 -> 5 | B8: 1A | C8: T139EES | D8: T454CBM-T290EMP | E8: RAMADHANI OMARY MNONJI | F8: PUMPI | G8: OFFLOADED | H8: 28 | I8: 35000 | J8: 35070 | K8: AN-HDAN | L8: 45890 | M8: ESL | N8: BC Raeda | O8: 45881 | P8: 45907 | Q8: 45892 | R8: 45990 | S8: 45994 | T8: 45998 | U8: 46007 | V8: 46011 | W8: 46011 | X8: 46011 | Y8: 46013 | Z8: 46014 | AA8: 46014 | AB8: 46014 | AC8: 46017 | AD8: COMPLETED | AE8: =MAX(0,Y8-X8) -> 2 | AF8: 7 | AG8: =MAX(0,AE8-AF8) -> 0 | AH8: 200 | AI8: =MAX(0,AG8*AH8) -> 0 | AJ8: =MAX(0,AC8-AB8) -> 3 | AK8: 2 | AL8: =MAX(0,AJ8-AK8) -> 1 | AM8: 200 | AN8: =MAX(0,AL8*AM8) -> 200 | AP8: =AO8+AN8+AI8 -> 200
A9: =ROW()-3 -> 6 | B9: 1A | C9: T328DWZ | D9: T390ALY | E9: VICTOR ANDREY MWAKALONGE | F9: PUMPI | G9: OFFLOADED | H9: 28 | I9: 35000 | J9: 35070 | K9: AN-HDAN | L9: 45890 | M9: ESL | N9: BC Raeda | O9: 45881 | P9: 45907 | Q9: 45892 | R9: 45990 | S9: 45994 | T9: 45998 | U9: 46006 | V9: 46010 | W9: 46010 | X9: 46010 | Y9: 46013 | Z9: 46014 | AA9: 46014 | AB9: 46014 | AC9: 46017 | AD9: COMPLETED | AE9: =MAX(0,Y9-X9) -> 3 | AF9: 7 | AG9: =MAX(0,AE9-AF9) -> 0 | AH9: 200 | AI9: =MAX(0,AG9*AH9) -> 0 | AJ9: =MAX(0,AC9-AB9) -> 3 | AK9: 2 | AL9: =MAX(0,AJ9-AK9) -> 1 | AM9: 200 | AN9: =MAX(0,AL9*AM9) -> 200 | AP9: =AO9+AN9+AI9 -> 200
A10: =ROW()-3 -> 7 | B10: 1A | C10: T337DWZ | D10: T900CBB-T134DUG | E10: MSINDU JUMA SALUM | F10: PUMPI | G10: OFFLOADED | H10: 28 | I10: 35000 | J10: 35070 | K10: AN-HDAN | L10: 45890 | M10: ESL | N10: BC Raeda | O10: 45881 | P10: 45907 | Q10: 45892 | R10: 45990 | S10: 45994 | T10: 45998 | U10: 46006 | V10: 46011 | W10: 46011 | X10: 46011 | Y10: 46013 | Z10: 46014 | AA10: 46014 | AB10: 46014 | AC10: 46017 | AD10: COMPLETED | AE10: =MAX(0,Y10-X10) -> 2 | AF10: 7 | AG10: =MAX(0,AE10-AF10) -> 0 | AH10: 200 | AI10: =MAX(0,AG10*AH10) -> 0 | AJ10: =MAX(0,AC10-AB10) -> 3 | AK10: 2 | AL10: =MAX(0,AJ10-AK10) -> 1 | AM10: 200 | AN10: =MAX(0,AL10*AM10) -> 200 | AO10: 0 | AP10: =AO10+AN10+AI10 -> 200
A11: =ROW()-3 -> 8 | B11: 1A | C11: T173EES | D11: T224DQD-T501DQD | E11: MAHMOUD AHMED MAYMUN | F11: PUMPI | G11: OFFLOADED | H11: 28 | I11: 35000 | J11: 35070 | K11: AN-HDAN | L11: 45890 | M11: ESL | N11: BC Raeda | O11: 45881 | P11: 45907 | Q11: 45892 | R11: 45990 | S11: 45992 | T11: 45997 | U11: 46003 | V11: 46006 | W11: 46006 | X11: 46006 | Y11: 46013 | Z11: 46013 | AA11: 46013 | AB11: 46013 | AC11: 46014 | AD11: COMPLETED | AE11: =MAX(0,Y11-X11) -> 7 | AF11: 7 | AG11: =MAX(0,AE11-AF11) -> 0 | AH11: 200 | AI11: =MAX(0,AG11*AH11) -> 0 | AJ11: =MAX(0,AC11-AB11) -> 1 | AK11: 2 | AL11: =MAX(0,AJ11-AK11) -> 0 | AM11: 200 | AN11: =MAX(0,AL11*AM11) -> 0 | AP11: =AO11+AN11+AI11 -> 0
A12: =ROW()-3 -> 9 | B12: 1A | C12: T383DZH | D12: T466CBM-T287EMP | E12: MOHAMED MUSSA MOHAMED | F12: PUMPI | G12: OFFLOADED | H12: 28 | I12: 35000 | J12: 35070 | K12: AN-HDAN | L12: 45890 | M12: ESL | N12: BC Raeda | O12: 45881 | P12: 45907 | Q12: 45892 | R12: 45990 | S12: 45992 | T12: 45997 | U12: 46003 | V12: 46006 | W12: 46006 | X12: 46006 | Y12: 46013 | Z12: 46013 | AA12: 46013 | AB12: 46013 | AC12: 46014 | AD12: COMPLETED | AE12: =MAX(0,Y12-X12) -> 7 | AF12: 7 | AG12: =MAX(0,AE12-AF12) -> 0 | AH12: 200 | AI12: =MAX(0,AG12*AH12) -> 0 | AJ12: =MAX(0,AC12-AB12) -> 1 | AK12: 2 | AL12: =MAX(0,AJ12-AK12) -> 0 | AM12: 200 | AN12: =MAX(0,AL12*AM12) -> 0 | AP12: =AO12+AN12+AI12 -> 0
A13: =ROW()-3 -> 10 | B13: 1A | C13: T545DMH | D13: T295BED-T202EMP | E13: PATRICK EMMANUEL MPEZYA | F13: PUMPI | G13: OFFLOADED | H13: 28 | I13: 35000 | J13: 35070 | K13: AN-HDAN | L13: 45890 | M13: ESL | N13: BC Raeda | O13: 45881 | P13: 45907 | Q13: 45892 | R13: 45992 | S13: 45995 | T13: 45999 | U13: 46003 | V13: 46006 | W13: 46006 | X13: 46006 | Y13: 46012 | Z13: 46012 | AA13: 46013 | AB13: 46013 | AC13: 46014 | AD13: COMPLETED | AE13: =MAX(0,Y13-X13) -> 6 | AF13: 7 | AG13: =MAX(0,AE13-AF13) -> 0 | AH13: 200 | AI13: =MAX(0,AG13*AH13) -> 0 | AJ13: =MAX(0,AC13-AB13) -> 1 | AK13: 2 | AL13: =MAX(0,AJ13-AK13) -> 0 | AM13: 200 | AN13: =MAX(0,AL13*AM13) -> 0 | AP13: =AO13+AN13+AI13 -> 0
A14: =ROW()-3 -> 11 | B14: 1A | C14: T381EFR | D14: T414EFX-T194EFX | E14: ABASI YAHAYA ALLY | F14: PUMPI | G14: OFFLOADED | H14: 29 | I14: 35000 | J14: 35070 | K14: AN-HDAN | L14: 45890 | M14: ESL | N14: BC Raeda | O14: 45881 | P14: 45907 | Q14: 45892 | R14: 45993 | S14: 45995 | T14: 45999 | U14: 46004 | V14: 46007 | W14: 46007 | X14: 46007 | Y14: 46011 | Z14: 46012 | AA14: 46013 | AB14: 46013 | AC14: 46014 | AD14: COMPLETED | AE14: =MAX(0,Y14-X14) -> 4 | AF14: 7 | AG14: =MAX(0,AE14-AF14) -> 0 | AH14: 200 | AI14: =MAX(0,AG14*AH14) -> 0 | AJ14: =MAX(0,AC14-AB14) -> 1 | AK14: 2 | AL14: =MAX(0,AJ14-AK14) -> 0 | AM14: 200 | AN14: =MAX(0,AL14*AM14) -> 0 | AP14: =AO14+AN14+AI14 -> 0
A15: =ROW()-3 -> 12 | B15: 1A | C15: T356EFR | D15: T188EFX-T186EFX | E15: SAID AHMED ABBAS | F15: PUMPI | G15: OFFLOADED | H15: 29 | I15: 35000 | J15: 35070 | K15: AN-HDAN | L15: 45890 | M15: ESL | N15: BC Raeda | O15: 45881 | P15: 45907 | Q15: 45892 | R15: 45993 | S15: 45995 | T15: 45999 | U15: 46003 | V15: 46006 | W15: 46006 | X15: 46006 | Y15: 46010 | Z15: 46010 | AA15: 46011 | AB15: 46011 | AC15: 46013 | AD15: COMPLETED | AE15: =MAX(0,Y15-X15) -> 4 | AF15: 7 | AG15: =MAX(0,AE15-AF15) -> 0 | AH15: 200 | AI15: =MAX(0,AG15*AH15) -> 0 | AJ15: =MAX(0,AC15-AB15) -> 2 | AK15: 2 | AL15: =MAX(0,AJ15-AK15) -> 0 | AM15: 200 | AN15: =MAX(0,AL15*AM15) -> 0 | AP15: =AO15+AN15+AI15 -> 0
A16: =ROW()-3 -> 13 | B16: 1A | C16: T787CCY | D16: T268DQD-T510DQD | E16: BAKARI OMARI MSAFA | F16: PUMPI | G16: OFFLOADED | H16: 28 | I16: 35000 | J16: 35070 | K16: AN-HDAN | L16: 45890 | M16: ESL | N16: BC Raeda | O16: 45881 | P16: 45907 | Q16: 45892 | R16: 45992 | S16: 45995 | T16: 45999 | U16: 46003 | V16: 46006 | W16: 46006 | X16: 46006 | Y16: 46010 | Z16: 46010 | AA16: 46011 | AB16: 46011 | AC16: 46013 | AD16: COMPLETED | AE16: =MAX(0,Y16-X16) -> 4 | AF16: 7 | AG16: =MAX(0,AE16-AF16) -> 0 | AH16: 200 | AI16: =MAX(0,AG16*AH16) -> 0 | AJ16: =MAX(0,AC16-AB16) -> 2 | AK16: 2 | AL16: =MAX(0,AJ16-AK16) -> 0 | AM16: 200 | AN16: =MAX(0,AL16*AM16) -> 0 | AP16: =AO16+AN16+AI16 -> 0
A17: =ROW()-3 -> 14 | B17: 1A | C17: T182EES | D17: T184BUF-T536EFH | E17: HEMED MWIDADI ALLY | F17: PUMPI | G17: OFFLOADED | H17: 28 | I17: 35000 | J17: 35070 | K17: AN-HDAN | L17: 45890 | M17: ESL | N17: BC Raeda | O17: 45881 | P17: 45907 | Q17: 45892 | R17: 45992 | S17: 45995 | T17: 45999 | U17: 46004 | V17: 46007 | W17: 46007 | X17: 46007 | Y17: 46011 | Z17: 46011 | AA17: 46011 | AB17: 46011 | AC17: 46013 | AD17: COMPLETED | AE17: =MAX(0,Y17-X17) -> 4 | AF17: 7 | AG17: =MAX(0,AE17-AF17) -> 0 | AH17: 200 | AI17: =MAX(0,AG17*AH17) -> 0 | AJ17: =MAX(0,AC17-AB17) -> 2 | AK17: 2 | AL17: =MAX(0,AJ17-AK17) -> 0 | AM17: 200 | AN17: =MAX(0,AL17*AM17) -> 0 | AP17: =AO17+AN17+AI17 -> 0
A18: =ROW()-3 -> 15 | B18: 1A | C18: T706EHZ | D18: T145EHW-T283EMP | E18: IDDY MOSHI IDDY | F18: PUMPI | G18: OFFLOADED | H18: 28 | I18: 35000 | J18: 35070 | K18: AN-HDAN | L18: 45890 | M18: ESL | N18: BC Raeda | O18: 45881 | P18: 45907 | Q18: 45892 | R18: 45992 | S18: 45995 | T18: 45999 | U18: 46004 | V18: 46007 | W18: 46007 | X18: 46007 | Y18: 46010 | Z18: 46010 | AA18: 46011 | AB18: 46011 | AC18: 46013 | AD18: COMPLETED | AE18: =MAX(0,Y18-X18) -> 3 | AF18: 7 | AG18: =MAX(0,AE18-AF18) -> 0 | AH18: 200 | AI18: =MAX(0,AG18*AH18) -> 0 | AJ18: =MAX(0,AC18-AB18) -> 2 | AK18: 2 | AL18: =MAX(0,AJ18-AK18) -> 0 | AM18: 200 | AN18: =MAX(0,AL18*AM18) -> 0 | AP18: =AO18+AN18+AI18 -> 0
A19: =ROW()-3 -> 16 | B19: 1A | C19: T657DQF | D19: T872DQF-T875DQF | E19: MRISHO ULEDI ALLY | F19: PUMPI | G19: OFFLOADED | H19: 28 | I19: 35000 | J19: 35070 | K19: AN-HDAN | L19: 45890 | M19: ESL | N19: BC Raeda | O19: 45881 | P19: 45907 | Q19: 45892 | R19: 45990 | S19: 45994 | T19: 45998 | U19: 46002 | V19: 46005 | W19: 46005 | X19: 46005 | Y19: 46011 | Z19: 46011 | AA19: 46011 | AB19: 46011 | AC19: 46013 | AD19: COMPLETED | AE19: =MAX(0,Y19-X19) -> 6 | AF19: 7 | AG19: =MAX(0,AE19-AF19) -> 0 | AH19: 200 | AI19: =MAX(0,AG19*AH19) -> 0 | AJ19: =MAX(0,AC19-AB19) -> 2 | AK19: 2 | AL19: =MAX(0,AJ19-AK19) -> 0 | AM19: 200 | AN19: =MAX(0,AL19*AM19) -> 0 | AP19: =AO19+AN19+AI19 -> 0
A20: =ROW()-3 -> 17 | B20: 1A | C20: T310EES | D20: T254DQD-T515DQD | E20: BAHATI A MWATUPOSOLE | F20: PUMPI | G20: OFFLOADED | H20: 28 | I20: 35000 | J20: 35070 | K20: AN-HDAN | L20: 45890 | M20: ESL | N20: BC Raeda | O20: 45881 | P20: 45907 | Q20: 45892 | R20: 45990 | S20: 45994 | T20: 45998 | U20: 46002 | V20: 46005 | W20: 46005 | X20: 46005 | Y20: 46011 | Z20: 46011 | AA20: 46011 | AB20: 46011 | AC20: 46013 | AD20: COMPLETED | AE20: =MAX(0,Y20-X20) -> 6 | AF20: 7 | AG20: =MAX(0,AE20-AF20) -> 0 | AH20: 200 | AI20: =MAX(0,AG20*AH20) -> 0 | AJ20: =MAX(0,AC20-AB20) -> 2 | AK20: 2 | AL20: =MAX(0,AJ20-AK20) -> 0 | AM20: 200 | AN20: =MAX(0,AL20*AM20) -> 0 | AP20: =AO20+AN20+AI20 -> 0
A21: =ROW()-3 -> 18 | B21: 1A | C21: T214EES | D21: T177BUF-T218EMM | E21: BARAKA FARUKU SANGA | F21: PUMPI | G21: OFFLOADED | H21: 28 | I21: 35000 | J21: 35070 | K21: AN-HDAN | L21: 45890 | M21: ESL | N21: BC Raeda | O21: 45881 | P21: 45907 | Q21: 45892 | R21: 45990 | S21: 45994 | T21: 45998 | U21: 46003 | V21: 46006 | W21: 46006 | X21: 46006 | Y21: 46010 | Z21: 46010 | AA21: 46011 | AB21: 46011 | AC21: 46013 | AD21: COMPLETED | AE21: =MAX(0,Y21-X21) -> 4 | AF21: 7 | AG21: =MAX(0,AE21-AF21) -> 0 | AH21: 200 | AI21: =MAX(0,AG21*AH21) -> 0 | AJ21: =MAX(0,AC21-AB21) -> 2 | AK21: 2 | AL21: =MAX(0,AJ21-AK21) -> 0 | AM21: 200 | AN21: =MAX(0,AL21*AM21) -> 0 | AP21: =AO21+AN21+AI21 -> 0
A22: =ROW()-3 -> 19 | B22: 1A | C22: T774EAE | D22: T180DED-T579DTR | E22: MWIDINI HASSANI OMARI | F22: PUMPI | G22: OFFLOADED | H22: 28 | I22: 35000 | J22: 35070 | K22: AN-HDAN | L22: 45890 | M22: ESL | N22: BC Raeda | O22: 45881 | P22: 45907 | Q22: 45892 | R22: 45990 | S22: 45992 | T22: 45997 | U22: 46003 | V22: 46006 | W22: 46006 | X22: 46006 | Y22: 46010 | Z22: 46010 | AA22: 46011 | AB22: 46011 | AC22: 46013 | AD22: COMPLETED | AE22: =MAX(0,Y22-X22) -> 4 | AF22: 7 | AG22: =MAX(0,AE22-AF22) -> 0 | AH22: 200 | AI22: =MAX(0,AG22*AH22) -> 0 | AJ22: =MAX(0,AC22-AB22) -> 2 | AK22: 2 | AL22: =MAX(0,AJ22-AK22) -> 0 | AM22: 200 | AN22: =MAX(0,AL22*AM22) -> 0 | AP22: =AO22+AN22+AI22 -> 0
... A30: =ROW()-3 -> 27 | B30: 1A | C30: T469DZH | D30: T208DZH-T193DZH | E30: ASAJILE RICHARD MWAKATUMBULA | F30: PUMPI | G30: OFFLOADED | H30: 28 | I30: 35000 | J30: 35070 | K30: AN-HDAN | L30: 45890 | M30: ESL | N30: BC Raeda | O30: 45881 | P30: 45907 | Q30: 45892 | R30: 45988 | S30: 45990 | T30: 45994 | U30: 45997 | V30: 46001 | W30: 46001 | X30: 46001 | Y30: 46005 | Z30: 46005 | AA30: 46006 | AB30: 46006 | AC30: 46007 | AD30: COMPLETED | AE30: =MAX(0,Y30-X30) -> 4 | AF30: 7 | AG30: =MAX(0,AE30-AF30) -> 0 | AH30: 200 | AI30: =MAX(0,AG30*AH30) -> 0 | AJ30: =MAX(0,AC30-AB30) -> 1 | AK30: 2 | AL30: =MAX(0,AJ30-AK30) -> 0 | AM30: 200 | AN30: =MAX(0,AL30*AM30) -> 0 | AP30: =AO30+AN30+AI30 -> 0
A31: =ROW()-3 -> 28 | B31: 1A | C31: T879CQL | D31: T375CRT-T426EFH | E31: JOHN PAULO MZALIFU | F31: PUMPI | G31: OFFLOADED | H31: 28 | I31: 35000 | J31: 35070 | K31: AN-HDAN | L31: 45890 | M31: ESL | N31: BC Raeda | O31: 45881 | P31: 45907 | Q31: 45892 | R31: 45990 | S31: 45990 | T31: 45994 | U31: 45996 | V31: 46001 | W31: 46001 | X31: 46001 | Y31: 46004 | Z31: 46004 | AA31: 46005 | AB31: 46005 | AC31: 46006 | AD31: COMPLETED | AE31: =MAX(0,Y31-X31) -> 3 | AF31: 7 | AG31: =MAX(0,AE31-AF31) -> 0 | AH31: 200 | AI31: =MAX(0,AG31*AH31) -> 0 | AJ31: =MAX(0,AC31-AB31) -> 1 | AK31: 2 | AL31: =MAX(0,AJ31-AK31) -> 0 | AM31: 200 | AN31: =MAX(0,AL31*AM31) -> 0 | AO31: 0 | AP31: =AO31+AN31+AI31 -> 0
A32: =ROW()-3 -> 29 | B32: 1A | C32: T232DNF | D32: T569CTF-T566DTR | E32: BASHIRI WAZIRI MFINANGA | F32: PUMPI | G32: OFFLOADED | H32: 28 | I32: 35000 | J32: 35070 | K32: AN-HDAN | L32: 45890 | M32: ESL | N32: BC Raeda | O32: 45881 | P32: 45907 | Q32: 45892 | R32: 45988 | S32: 45990 | T32: 45994 | U32: 45998 | V32: 46002 | W32: 46002 | X32: 46002 | Y32: 46004 | Z32: 46004 | AA32: 46005 | AB32: 46005 | AC32: 46006 | AD32: COMPLETED | AE32: =MAX(0,Y32-X32) -> 2 | AF32: 7 | AG32: =MAX(0,AE32-AF32) -> 0 | AH32: 200 | AI32: =MAX(0,AG32*AH32) -> 0 | AJ32: =MAX(0,AC32-AB32) -> 1 | AK32: 2 | AL32: =MAX(0,AJ32-AK32) -> 0 | AM32: 200 | AN32: =MAX(0,AL32*AM32) -> 0 | AP32: =AO32+AN32+AI32 -> 0
A33: =ROW()-3 -> 30 | B33: 1A | C33: T621DPV | D33: T245ARR-T568DTR | E33: FRANSIS IZDOLI KALINGA | F33: PUMPI | G33: OFFLOADED | H33: 28 | I33: 35000 | J33: 35070 | K33: AN-HDAN | L33: 45890 | M33: ESL | N33: BC Raeda | O33: 45881 | P33: 45907 | Q33: 45892 | R33: 45988 | S33: 45990 | T33: 45994 | U33: 45997 | V33: 46000 | W33: 46000 | X33: 46000 | Y33: 46003 | Z33: 46004 | AA33: 46005 | AB33: 46005 | AC33: 46006 | AD33: COMPLETED | AE33: =MAX(0,Y33-X33) -> 3 | AF33: 7 | AG33: =MAX(0,AE33-AF33) -> 0 | AH33: 200 | AI33: =MAX(0,AG33*AH33) -> 0 | AJ33: =MAX(0,AC33-AB33) -> 1 | AK33: 2 | AL33: =MAX(0,AJ33-AK33) -> 0 | AM33: 200 | AN33: =MAX(0,AL33*AM33) -> 0 | AO33: 0 | AP33: =AO33+AN33+AI33 -> 0
A34: =ROW()-3 -> 31 | B34: 1A | C34: T660DQF | D34: T226DQD-T509DQD | E34: SELEMANI MZEE MNEMO | F34: PUMPI | G34: OFFLOADED | H34: 28 | I34: 35000 | J34: 35070 | K34: AN-HDAN | L34: 45890 | M34: ESL | N34: BC Raeda | O34: 45881 | P34: 45907 | Q34: 45892 | R34: 45988 | S34: 45990 | T34: 45994 | U34: 45996 | V34: 46000 | W34: 46000 | X34: 46000 | Y34: 46003 | Z34: 46004 | AA34: 46005 | AB34: 46005 | AC34: 46006 | AD34: COMPLETED | AE34: =MAX(0,Y34-X34) -> 3 | AF34: 7 | AG34: =MAX(0,AE34-AF34) -> 0 | AH34: 200 | AI34: =MAX(0,AG34*AH34) -> 0 | AJ34: =MAX(0,AC34-AB34) -> 1 | AK34: 2 | AL34: =MAX(0,AJ34-AK34) -> 0 | AM34: 200 | AN34: =MAX(0,AL34*AM34) -> 0 | AO34: 0 | AP34: =AO34+AN34+AI34 -> 0
A35: =ROW()-3 -> 32 | B35: 1A | C35: T349DWZ | D35: T190DXQ-T191DXQ | E35: CHRISTOPHER ADELIN MASAWE | F35: PUMPI | G35: OFFLOADED | H35: 29 | I35: 36250 | J35: 36323 | K35: AN-HDAN | L35: 45890 | M35: ESL | N35: BC Raeda | O35: 45881 | P35: 45907 | Q35: 45892 | R35: 45988 | S35: 45990 | T35: 45994 | U35: 45996 | V35: 46001 | W35: 46001 | X35: 46001 | Y35: 46004 | Z35: 46004 | AA35: 46005 | AB35: 46005 | AC35: 46006 | AD35: COMPLETED | AE35: =MAX(0,Y35-X35) -> 3 | AF35: 7 | AG35: =MAX(0,AE35-AF35) -> 0 | AH35: 200 | AI35: =MAX(0,AG35*AH35) -> 0 | AJ35: =MAX(0,AC35-AB35) -> 1 | AK35: 2 | AL35: =MAX(0,AJ35-AK35) -> 0 | AM35: 200 | AN35: =MAX(0,AL35*AM35) -> 0 | AP35: =AO35+AN35+AI35 -> 0
A36: =ROW()-3 -> 33 | B36: 1A | C36: T292DRM | D36: T978BXK | E36: IDDI TITUSI MKENGE | F36: PUMPI | G36: OFFLOADED | H36: 30 | I36: 37500 | J36: 37605 | K36: AN-HDAN | L36: 45890 | M36: ESL | N36: BC Raeda | O36: 45881 | P36: 45907 | Q36: 45892 | R36: 45988 | S36: 45990 | T36: 45994 | U36: 45996 | V36: 45998 | W36: 45998 | X36: 45998 | Y36: 46000 | Z36: 46001 | AA36: 46001 | AB36: 46001 | AC36: 46002 | AD36: COMPLETED | AE36: =MAX(0,Y36-X36) -> 2 | AF36: 7 | AG36: =MAX(0,AE36-AF36) -> 0 | AH36: 200 | AI36: =MAX(0,AG36*AH36) -> 0 | AJ36: =MAX(0,AC36-AB36) -> 1 | AK36: 2 | AL36: =MAX(0,AJ36-AK36) -> 0 | AM36: 200 | AN36: =MAX(0,AL36*AM36) -> 0 | AP36: =AO36+AN36+AI36 -> 0
A37: =ROW()-3 -> 34 | B37: 1A | C37: T904ECV | D37: T717DEG | E37: BAKARI SALIM BAKARI | F37: PUMPI | G37: OFFLOADED | H37: 29 | I37: 36250 | J37: 36323 | K37: AN-HDAN | L37: 45890 | M37: ESL | N37: BC Raeda | O37: 45881 | P37: 45907 | Q37: 45892 | R37: 45988 | S37: 45990 | T37: 45994 | U37: 45996 | V37: 45998 | W37: 45998 | X37: 45998 | Y37: 45999 | Z37: 46001 | AA37: 46001 | AB37: 46001 | AC37: 46002 | AD37: COMPLETED | AE37: =MAX(0,Y37-X37) -> 1 | AF37: 7 | AG37: =MAX(0,AE37-AF37) -> 0 | AH37: 200 | AI37: =MAX(0,AG37*AH37) -> 0 | AJ37: =MAX(0,AC37-AB37) -> 1 | AK37: 2 | AL37: =MAX(0,AJ37-AK37) -> 0 | AM37: 200 | AN37: =MAX(0,AL37*AM37) -> 0 | AP37: =AO37+AN37+AI37 -> 0
A38: =ROW()-3 -> 35 | B38: 1A | C38: T327DWZ | D38: T208DSK | E38: JUMA KHALFANI SEMINDU | F38: PUMPI | G38: OFFLOADED | H38: 29 | I38: 36250 | J38: 36323 | K38: AN-HDAN | L38: 45890 | M38: ESL | N38: BC Raeda | O38: 45881 | P38: 45907 | Q38: 45892 | R38: 45955 | S38: 45957 | T38: 45966 | U38: 45970 | V38: 45987 | W38: 45987 | X38: 45987 | Y38: 45990 | Z38: 45990 | AA38: 45992 | AB38: 45992 | AC38: 45993 | AD38: COMPLETED | AE38: =MAX(0,Y38-X38) -> 3 | AF38: 7 | AG38: =MAX(0,AE38-AF38) -> 0 | AH38: 200 | AI38: =MAX(0,AG38*AH38) -> 0 | AJ38: =MAX(0,AC38-AB38) -> 1 | AK38: 2 | AL38: =MAX(0,AJ38-AK38) -> 0 | AM38: 200 | AN38: =MAX(0,AL38*AM38) -> 0 | AO38: 0 | AP38: =AO38+AN38+AI38 -> 0
A39: =ROW()-3 -> 36 | B39: 1A | C39: T299DRF | D39: T497DCA | E39: JUMA RAMADHAN GOGO | F39: PUMPI | G39: OFFLOADED | H39: 29 | I39: 36323 | J39: 56000 | K39: AN-HDAN | L39: 45890 | M39: ESL | N39: BC Raeda | O39: 45881 | P39: 45907 | Q39: 45892 | R39: 45971 | S39: 45972 | T39: 45974 | U39: 45978 | V39: 45981 | W39: 45981 | X39: 45981 | Y39: 45985 | Z39: 45986 | AA39: 45986 | AB39: 45986 | AC39: 45987 | AD39: COMPLETED | AE39: =MAX(0,Y39-X39) -> 4 | AF39: 7 | AG39: =MAX(0,AE39-AF39) -> 0 | AH39: 200 | AI39: =MAX(0,AG39*AH39) -> 0 | AJ39: =MAX(0,AC39-AB39) -> 1 | AK39: 2 | AL39: =MAX(0,AJ39-AK39) -> 0 | AM39: 200 | AN39: =MAX(0,AL39*AM39) -> 0 | AP39: =AO39+AN39+AI39 -> 0
A40: =ROW()-3 -> 37 | B40: 1A | C40: T160EES | D40: T730BAK-T539EFH | E40: HUSSEIN SALEH MGENI | F40: PUMPI | G40: OFFLOADED | H40: 28 | I40: 35070 | J40: 56000 | K40: AN-HDAN | L40: 45890 | M40: ESL | N40: BC Raeda | O40: 45881 | P40: 45907 | Q40: 45892 | R40: 45971 | S40: 45972 | T40: 45974 | U40: 45979 | V40: 45981 | W40: 45981 | X40: 45981 | Y40: 45984 | Z40: 45984 | AA40: 45985 | AB40: 45985 | AC40: 45986 | AD40: COMPLETED | AE40: =MAX(0,Y40-X40) -> 3 | AF40: 7 | AG40: =MAX(0,AE40-AF40) -> 0 | AH40: 200 | AI40: =MAX(0,AG40*AH40) -> 0 | AJ40: =MAX(0,AC40-AB40) -> 1 | AK40: 2 | AL40: =MAX(0,AJ40-AK40) -> 0 | AM40: 200 | AN40: =MAX(0,AL40*AM40) -> 0 | AP40: =AO40+AN40+AI40 -> 0
A41: =ROW()-3 -> 38 | B41: 1A | C41: T141EES | D41: T998ANZ | E41: SHUKURU OMARY FUNUA | F41: PUMPI | G41: OFFLOADED | H41: 29 | I41: 36250 | J41: 36323 | K41: AN-HDAN | L41: 45890 | M41: ESL | N41: BC Raeda | O41: 45881 | P41: 45907 | Q41: 45892 | R41: 45949 | S41: 45950 | T41: 45953 | U41: 45969 | V41: 45978 | W41: 45978 | X41: 45978 | Y41: 45984 | Z41: 45984 | AA41: 45985 | AB41: 45985 | AC41: 45985 | AD41: COMPLETED | AE41: =MAX(0,Y41-X41) -> 6 | AF41: 7 | AG41: =MAX(0,AE41-AF41) -> 0 | AH41: 200 | AI41: =MAX(0,AG41*AH41) -> 0 | AJ41: =MAX(0,AC41-AB41) -> 0 | AK41: 2 | AL41: =MAX(0,AJ41-AK41) -> 0 | AM41: 200 | AN41: =MAX(0,AL41*AM41) -> 0 | AP41: =AO41+AN41+AI41 -> 0
A42: =ROW()-3 -> 39 | B42: 1A | C42: T432BVZ | D42: T748CVC-T246EMP | E42: HAMIS RASHID MIHAYO | F42: PUMPI | G42: OFFLOADED | H42: 28 | I42: 35000 | J42: 35070 | K42: AN-HDAN | L42: 45890 | M42: ESL | N42: BC Raeda | O42: 45881 | P42: 45907 | Q42: 45892 | R42: 45955 | S42: 45957 | T42: 45966 | U42: 45979 | V42: 45981 | W42: 45981 | X42: 45981 | Y42: 45984 | Z42: 45984 | AA42: 45985 | AB42: 45985 | AC42: 45985 | AD42: COMPLETED | AE42: =MAX(0,Y42-X42) -> 3 | AF42: 7 | AG42: =MAX(0,AE42-AF42) -> 0 | AH42: 200 | AI42: =MAX(0,AG42*AH42) -> 0 | AJ42: =MAX(0,AC42-AB42) -> 0 | AK42: 2 | AL42: =MAX(0,AJ42-AK42) -> 0 | AM42: 200 | AN42: =MAX(0,AL42*AM42) -> 0 | AP42: =AO42+AN42+AI42 -> 0
A43: =ROW()-3 -> 40 | B43: 1A | C43: T461DZH | D43: T503AUU-T245EMP | E43: DEOGRATIAS TADEUS TARIMO | F43: PUMPI | G43: OFFLOADED | H43: 28 | I43: 35070 | J43: 56000 | K43: AN-HDAN | L43: 45890 | M43: ESL | N43: BC Raeda | O43: 45881 | P43: 45907 | Q43: 45892 | R43: 45971 | S43: 45972 | T43: 45974 | U43: 45978 | V43: 45981 | W43: 45981 | X43: 45981 | Y43: 45984 | Z43: 45984 | AA43: 45985 | AB43: 45985 | AC43: 45985 | AD43: COMPLETED | AE43: =MAX(0,Y43-X43) -> 3 | AF43: 7 | AG43: =MAX(0,AE43-AF43) -> 0 | AH43: 200 | AI43: =MAX(0,AG43*AH43) -> 0 | AJ43: =MAX(0,AC43-AB43) -> 0 | AK43: 2 | AL43: =MAX(0,AJ43-AK43) -> 0 | AM43: 200 | AN43: =MAX(0,AL43*AM43) -> 0 | AP43: =AO43+AN43+AI43 -> 0
A44: =ROW()-3 -> 41 | B44: 1A | C44: T418BXV | D44: T196BED-T677EFH | E44: JOSHUA BROWN NZAVIKE | F44: PUMPI | G44: OFFLOADED | H44: 28 | I44: 35070 | J44: 56000 | K44: AN-HDAN | L44: 45890 | M44: ESL | N44: BC Raeda | O44: 45881 | P44: 45907 | Q44: 45892 | R44: 45971 | S44: 45972 | T44: 45974 | U44: 45979 | V44: 45981 | W44: 45981 | X44: 45981 | Y44: 45984 | Z44: 45984 | AA44: 45985 | AB44: 45985 | AC44: 45985 | AD44: COMPLETED | AE44: =MAX(0,Y44-X44) -> 3 | AF44: 7 | AG44: =MAX(0,AE44-AF44) -> 0 | AH44: 200 | AI44: =MAX(0,AG44*AH44) -> 0 | AJ44: =MAX(0,AC44-AB44) -> 0 | AK44: 2 | AL44: =MAX(0,AJ44-AK44) -> 0 | AM44: 200 | AN44: =MAX(0,AL44*AM44) -> 0 | AP44: =AO44+AN44+AI44 -> 0
A45: =ROW()-3 -> 42 | B45: 1A | C45: T659CJT | D45: T187BUF-T229EMP | E45: MLOWE MAIKO BENJAMIN | F45: PUMPI | G45: OFFLOADED | H45: 28 | I45: 35070 | J45: 56000 | K45: AN-HDAN | L45: 45890 | M45: ESL | N45: BC Raeda | O45: 45881 | P45: 45907 | Q45: 45892 | R45: 45971 | S45: 45972 | T45: 45974 | U45: 45978 | V45: 45980 | W45: 45980 | X45: 45980 | Y45: 45984 | Z45: 45984 | AA45: 45985 | AB45: 45985 | AC45: 45985 | AD45: COMPLETED | AE45: =MAX(0,Y45-X45) -> 4 | AF45: 7 | AG45: =MAX(0,AE45-AF45) -> 0 | AH45: 200 | AI45: =MAX(0,AG45*AH45) -> 0 | AJ45: =MAX(0,AC45-AB45) -> 0 | AK45: 2 | AL45: =MAX(0,AJ45-AK45) -> 0 | AM45: 200 | AN45: =MAX(0,AL45*AM45) -> 0 | AP45: =AO45+AN45+AI45 -> 0
A46: =ROW()-3 -> 43 | B46: 1A | C46: T308BZY | D46: T405BQX-T260EMP | E46: KHAMIS MOHAMED ABDALLAH | F46: PUMPI | G46: OFFLOADED | H46: 28 | I46: 35000 | J46: 35070 | K46: AN-HDAN | L46: 45890 | M46: ESL | N46: BC Raeda | O46: 45881 | P46: 45907 | Q46: 45892 | R46: 45955 | S46: 45957 | T46: 45971 | U46: 45978 | V46: 45980 | W46: 45980 | X46: 45980 | Y46: 45981 | Z46: 45982 | AA46: 45982 | AB46: 45982 | AC46: 45982 | AD46: COMPLETED | AE46: =MAX(0,Y46-X46) -> 1 | AF46: 7 | AG46: =MAX(0,AE46-AF46) -> 0 | AH46: 200 | AI46: =MAX(0,AG46*AH46) -> 0 | AJ46: =MAX(0,AC46-AB46) -> 0 | AK46: 2 | AL46: =MAX(0,AJ46-AK46) -> 0 | AM46: 200 | AN46: =MAX(0,AL46*AM46) -> 0 | AP46: =AO46+AN46+AI46 -> 0
A47: =ROW()-3 -> 44 | B47: 1A | C47: T578DMJ | D47: T177DCZ-T556DTR | E47: BASHIRU JUMA SOMBI | F47: PUMPI | G47: OFFLOADED | H47: 28 | I47: 35000 | J47: 35070 | K47: AN-HDAN | L47: 45890 | M47: ESL | N47: BC Raeda | O47: 45881 | P47: 45907 | Q47: 45892 | R47: 45955 | S47: 45957 | T47: 45966 | U47: 45969 | V47: 45971 | W47: 45971 | X47: 45971 | Y47: 45974 | Z47: 45974 | AA47: 45975 | AB47: 45976 | AC47: 45978 | AD47: COMPLETED | AE47: =MAX(0,Y47-X47) -> 3 | AF47: 7 | AG47: =MAX(0,AE47-AF47) -> 0 | AH47: 200 | AI47: =MAX(0,AG47*AH47) -> 0 | AJ47: =MAX(0,AC47-AB47) -> 2 | AK47: 2 | AL47: =MAX(0,AJ47-AK47) -> 0 | AM47: 200 | AN47: =MAX(0,AL47*AM47) -> 0 | AP47: =AO47+AN47+AI47 -> 0
...

Sheet BL-1A-Kolwezi
A1: DAILY TRACKING REPORT - FORWARDING | E1: =TODAY() -> 46045 | F1: BC RAEDA | G1: H-DAN | H1: 3992 | I1: 4990 | J1: 5003.991 | M1: GT OCEAN TRANSPORTATION LIMITED | T1: GT OCEAN TRANSPORTATION LIMITED | AB1: GT OCEAN TRANSPORTATION LIMITED | AN1: Total Amount
A2: 序号 | B2: 提单号 | C2: 卡车牌号 | D2: 拖车牌号 | E2: 司机姓名 | F2: 目的地 | G2: 当前位置 | H2: 吨袋/bags | I2: 净重/N.W. | J2: 毛重/G.W. | L2: 文件接收 | M2: 船司 | N2: 船名 | O2: 预计抵港 | P2: 实际靠泊 | Q2: 船司放行 | R2: 装运时间 | S2: 起运时间 | T2: 到达TUNDUMA | U2: NAKONDE出发 | V2: 到达卡松ZAMBIA | W2: 卡松ZAMBIA出发 | X2: 到达卡松DRC | Y2: 卡松出发DRC | AB2: 到达目的地 | AC2: 卸货时间 | AD2: 备注 | AE2: Border Delays | AI2: =SUM(AI6:AI22) -> 0 | AJ2: Offloading Delays | AN2: =SUM(AN6:AN22) -> 600 | AO2: =SUM(AO6:AO22) -> 200 | AP2: =SUM(AI2:AO2) -> 800
A3: No. | B3: B/L No. | C3: TRUCK NUMBER | D3: TRAILER NUMBER | E3: DRIVER NAME | F3: FINAL DESTINATION | G3: TRUCK POSITION | H3: =SUM(H5:H202) -> 476 | I3: =SUM(I5:I202)/1000 -> 595 | J3: =SUM(J5:J202)/1000 -> 596.216 | K3: HDAN | L3: DOCUMENTS RECEIVED | M3: SHIPPING LINE | N3: VESSEL | O3: ETA | P3: ATB | Q3: LINE RELEASE | R3: DATE LOADED | S3: DISPATCH DATE | T3: ARRIVED TUNDUMA BORDER | U3: DEPARTED NAKONDE | V3: K-LESA ZAMBIA ARRIVED | W3: K-LESA ZAMBIA DEPARTED | X3: K-LESA DRC ARRIVED | Y3: K-LESA DRC DEPARTED | Z3: L-MBASHI ARRIVED | AA3: DEPARTED L-MBASHI | AB3: ARRIVED DESTINATION | AC3: OFFLOADED | AD3: COMMENTS | AE3: Border Days | AF3: Free days | AG3: Chargable Days | AH3: Chargable Rate | AI3: Border Delays Amt | AJ3: Offloading Days | AK3: Free days | AL3: Chargable Days | AM3: Chargable Rate | AN3: Offloading Delays Amt | AO3: Parking Charges Amount | AP3: TOTAL
A4: =ROW()-3 -> 1 | B4: 1A | C4: T551DCZ | D4: T515BWD | E4: JUMAA HALFAN KIPANGA | F4: KOLWEZI | G4: OFFLOADED | H4: 29 | I4: 36250 | J4: 36323 | K4: AN-HDAN | L4: 45890 | M4: ESL | N4: BC Raeda | O4: 45881 | P4: 45907 | Q4: 45892 | R4: 45990 | S4: 46002 | T4: 46013 | U4: 46017 | V4: 46023 | W4: 46023 | X4: 46023 | Y4: 46027 | Z4: 46027 | AA4: 46028 | AB4: 46031 | AC4: 46034 | AD4: COMPLETED | AE4: =MAX(0,Y4-X4) -> 4 | AF4: 7 | AG4: =MAX(0,AE4-AF4) -> 0 | AH4: 200 | AI4: =MAX(0,AG4*AH4) -> 0 | AJ4: =MAX(0,AC4-AB4) -> 3 | AK4: 2 | AL4: =MAX(0,AJ4-AK4) -> 1 | AM4: 200 | AN4: =MAX(0,AL4*AM4) -> 200 | AP4: =AO4+AN4+AI4 -> 200
A5: =ROW()-3 -> 2 | B5: 1A | C5: T249CVP | D5: T759AXN-T341DXR | E5: JUMANNE MAMBO | F5: KOLWEZI | G5: OFFLOADED | H5: 28 | I5: 35000 | J5: 35070 | K5: AN-HDAN | L5: 45890 | M5: ESL | N5: BC Raeda | O5: 45881 | P5: 45907 | Q5: 45892 | R5: 45951 | S5: 45995 | T5: 45999 | U5: 46006 | V5: 46011 | W5: 46011 | X5: 46011 | Y5: 46013 | Z5: 46013 | AA5: 46014 | AB5: 46015 | AC5: 46015 | AD5: COMPLETED | AE5: =MAX(0,Y5-X5) -> 2 | AF5: 7 | AG5: =MAX(0,AE5-AF5) -> 0 | AH5: 200 | AI5: =MAX(0,AG5*AH5) -> 0 | AJ5: =MAX(0,AC5-AB5) -> 0 | AK5: 2 | AL5: =MAX(0,AJ5-AK5) -> 0 | AM5: 200 | AN5: =MAX(0,AL5*AM5) -> 0 | AO5: 0 | AP5: =AO5+AN5+AI5 -> 0
A6: =ROW()-3 -> 3 | B6: 1A | C6: T623DPV | D6: T101APA | E6: FREDRICK LUCAS NYAMHANGA | F6: KOLWEZI | G6: OFFLOADED | H6: 24 | I6: 30000 | J6: 30084 | K6: AN-HDAN | L6: 45890 | M6: ESL | N6: BC Raeda | O6: 45881 | P6: 45907 | Q6: 45892 | R6: 45951 | S6: 45952 | T6: 45956 | U6: 45964 | V6: 45966 | W6: 45966 | X6: 45966 | Y6: 45969 | Z6: 45969 | AA6: 45974 | AB6: 45975 | AC6: 45978 | AD6: COMPLETED | AE6: =MAX(0,Y6-X6) -> 3 | AF6: 7 | AG6: =MAX(0,AE6-AF6) -> 0 | AH6: 200 | AI6: =MAX(0,AG6*AH6) -> 0 | AJ6: =MAX(0,AC6-AA7) -> 4 | AK6: 2 | AL6: =MAX(0,AJ6-AK6) -> 2 | AM6: 200 | AN6: =MAX(0,AL6*AM6) -> 400 | AO6: 0 | AP6: =AO6+AN6+AI6 -> 400
A7: =ROW()-3 -> 4 | B7: 1A | C7: T451EFR | D7: T490ELF-T208EMP | E7: SAID MOHAMED KHALFANI | F7: KOLWEZI | G7: OFFLOADED | H7: 28 | I7: 35000 | J7: 35070 | K7: AN-HDAN | L7: 45890 | M7: ESL | N7: BC Raeda | O7: 45881 | P7: 45907 | Q7: 45892 | R7: 45951 | S7: 45952 | T7: 45956 | U7: 45963 | V7: 45968 | W7: 45968 | X7: 45968 | Y7: 45971 | Z7: 45972 | AA7: 45974 | AB7: 45975 | AC7: 45977 | AD7: COMPLETED | AE7: =MAX(0,Y7-X7) -> 3 | AF7: 7 | AG7: =MAX(0,AE7-AF7) -> 0 | AH7: 200 | AI7: =MAX(0,AG7*AH7) -> 0 | AJ7: =MAX(0,AC7-AB7) -> 2 | AK7: 2 | AL7: =MAX(0,AJ7-AK7) -> 0 | AM7: 200 | AN7: =MAX(0,AL7*AM7) -> 0 | AO7: 0 | AP7: =AO7+AN7+AI7 -> 0
A8: =ROW()-3 -> 5 | B8: 1A | C8: T645CJT | D8: T445CBM-T984DWJ | E8: SALIM ZUBERI ALLY | F8: KOLWEZI | G8: OFFLOADED | H8: 28 | I8: 35000 | J8: 35070 | K8: AN-HDAN | L8: 45890 | M8: ESL | N8: BC Raeda | O8: 45881 | P8: 45907 | Q8: 45892 | R8: 45951 | S8: 45952 | T8: 45956 | U8: 45963 | V8: 45967 | W8: 45967 | X8: 45967 | Y8: 45972 | Z8: 45973 | AA8: 45973 | AB8: 45973 | AC8: 45974 | AD8: COMPLETED | AE8: =MAX(0,Y8-X8) -> 5 | AF8: 7 | AG8: =MAX(0,AE8-AF8) -> 0 | AH8: 200 | AI8: =MAX(0,AG8*AH8) -> 0 | AJ8: =MAX(0,AC8-AB8) -> 1 | AK8: 2 | AL8: =MAX(0,AJ8-AK8) -> 0 | AM8: 200 | AN8: =MAX(0,AL8*AM8) -> 0 | AO8: 0 | AP8: =AO8+AN8+AI8 -> 0
A9: =ROW()-3 -> 6 | B9: 1A | C9: T338EFR | D9: T371CRT-T102DWK | E9: NDANDA MATHIAS GEORGE | F9: KOLWEZI | G9: OFFLOADED | H9: 28 | I9: 35000 | J9: 35070 | K9: AN-HDAN | L9: 45890 | M9: ESL | N9: BC Raeda | O9: 45881 | P9: 45907 | Q9: 45892 | R9: 45951 | S9: 45952 | T9: 45956 | U9: 45965 | V9: 45967 | W9: 45967 | X9: 45967 | Y9: 45970 | Z9: 45970 | AA9: 45971 | AB9: 45972 | AC9: 45972 | AD9: COMPLETED | AE9: =MAX(0,Y9-X9) -> 3 | AF9: 7 | AG9: =MAX(0,AE9-AF9) -> 0 | AH9: 200 | AI9: =MAX(0,AG9*AH9) -> 0 | AJ9: =MAX(0,AC9-AB9) -> 0 | AK9: 2 | AL9: =MAX(0,AJ9-AK9) -> 0 | AM9: 200 | AN9: =MAX(0,AL9*AM9) -> 0 | AP9: =AO9+AN9+AI9 -> 0
A10: =ROW()-3 -> 7 | B10: 1A | C10: T459DMH | D10: T661BAK-T417EFH | E10: AISHA HUSSENI RAMADHANI | F10: KOLWEZI | G10: OFFLOADED | H10: 28 | I10: 35000 | J10: 35070 | K10: AN-HDAN | L10: 45890 | M10: ESL | N10: BC Raeda | O10: 45881 | P10: 45907 | Q10: 45892 | R10: 45951 | S10: 45952 | T10: 45956 | U10: 45958 | V10: 45962 | W10: 45962 | X10: 45962 | Y10: 45966 | Z10: 45966 | AA10: 45967 | AB10: 45968 | AC10: 45971 | AD10: COMPLETED | AE10: =MAX(0,Y10-X10) -> 4 | AF10: 7 | AG10: =MAX(0,AE10-AF10) -> 0 | AH10: 200 | AI10: =MAX(0,AG10*AH10) -> 0 | AJ10: =MAX(0,AC10-AB10) -> 3 | AK10: 2 | AL10: =MAX(0,AJ10-AK10) -> 1 | AM10: 200 | AN10: =MAX(0,AL10*AM10) -> 200 | AO10: 25 | AP10: =AO10+AN10+AI10 -> 225
A11: =ROW()-3 -> 8 | B11: 1A | C11: T599BXN | D11: T186BED-T689DUQ | E11: MAHAMOOD JAPANIS DEVILLIES | F11: KOLWEZI | G11: OFFLOADED | H11: 28 | I11: 35000 | J11: 35070 | K11: AN-HDAN | L11: 45890 | M11: ESL | N11: BC Raeda | O11: 45881 | P11: 45907 | Q11: 45892 | R11: 45951 | S11: 45952 | T11: 45957 | U11: 45963 | V11: 45966 | W11: 45966 | X11: 45966 | Y11: 45967 | Z11: 45967 | AA11: 45968 | AB11: 45968 | AC11: 45969 | AD11: COMPLETED | AE11: =MAX(0,Y11-X11) -> 1 | AF11: 7 | AG11: =MAX(0,AE11-AF11) -> 0 | AH11: 200 | AI11: =MAX(0,AG11*AH11) -> 0 | AJ11: =MAX(0,AC11-AB11) -> 1 | AK11: 2 | AL11: =MAX(0,AJ11-AK11) -> 0 | AM11: 200 | AN11: =MAX(0,AL11*AM11) -> 0 | AO11: 0 | AP11: =AO11+AN11+AI11 -> 0
A12: =ROW()-3 -> 9 | B12: 1A | C12: T935CAS | D12: T118BFS-T408DTF | E12: DANIFRED F DEDU | F12: KOLWEZI | G12: OFFLOADED | H12: 28 | I12: 35000 | J12: 35070 | K12: AN-HDAN | L12: 45890 | M12: ESL | N12: BC Raeda | O12: 45881 | P12: 45907 | Q12: 45892 | R12: 45951 | S12: 45952 | T12: 45956 | U12: 45963 | V12: 45966 | W12: 45966 | X12: 45966 | Y12: 45967 | Z12: 45967 | AA12: 45968 | AB12: 45968 | AC12: 45969 | AD12: COMPLETED | AE12: =MAX(0,Y12-X12) -> 1 | AF12: 7 | AG12: =MAX(0,AE12-AF12) -> 0 | AH12: 200 | AI12: =MAX(0,AG12*AH12) -> 0 | AJ12: =MAX(0,AC12-AB12) -> 1 | AK12: 2 | AL12: =MAX(0,AJ12-AK12) -> 0 | AM12: 200 | AN12: =MAX(0,AL12*AM12) -> 0 | AO12: 0 | AP12: =AO12+AN12+AI12 -> 0
A13: =ROW()-3 -> 10 | B13: 1A | C13: T400DZH | D13: T502BWD-T289EMP | E13: JERRY KALEB MAZENGO | F13: KOLWEZI | G13: OFFLOADED | H13: 28 | I13: 35000 | J13: 35070 | K13: AN-HDAN | L13: 45890 | M13: ESL | N13: BC Raeda | O13: 45881 | P13: 45907 | Q13: 45892 | R13: 45951 | S13: 45952 | T13: 45956 | U13: 45963 | V13: 45966 | W13: 45966 | X13: 45966 | Y13: 45967 | Z13: 45967 | AA13: 45968 | AB13: 45968 | AC13: 45969 | AD13: COMPLETED | AE13: =MAX(0,Y13-X13) -> 1 | AF13: 7 | AG13: =MAX(0,AE13-AF13) -> 0 | AH13: 200 | AI13: =MAX(0,AG13*AH13) -> 0 | AJ13: =MAX(0,AC13-AB13) -> 1 | AK13: 2 | AL13: =MAX(0,AJ13-AK13) -> 0 | AM13: 200 | AN13: =MAX(0,AL13*AM13) -> 0 | AO13: 0 | AP13: =AO13+AN13+AI13 -> 0
A14: =ROW()-3 -> 11 | B14: 1A | C14: T873DRL | D14: T478CRA | E14: CASTORY HENRY MWILAPWA | F14: KOLWEZI | G14: OFFLOADED | H14: 29 | I14: 36250 | J14: 36323 | K14: AN-HDAN | L14: 45890 | M14: ESL | N14: BC Raeda | O14: 45881 | P14: 45907 | Q14: 45892 | R14: 45949 | S14: 45950 | T14: 45953 | U14: 45957 | V14: 45962 | W14: 45962 | X14: 45962 | Y14: 45965 | Z14: 45965 | AA14: 45966 | AB14: 45966 | AC14: 45968 | AD14: COMPLETED | AE14: =MAX(0,Y14-X14) -> 3 | AF14: 7 | AG14: =MAX(0,AE14-AF14) -> 0 | AH14: 200 | AI14: =MAX(0,AG14*AH14) -> 0 | AJ14: =MAX(0,AC14-AB14) -> 2 | AK14: 2 | AL14: =MAX(0,AJ14-AK14) -> 0 | AM14: 200 | AN14: =MAX(0,AL14*AM14) -> 0 | AO14: 25 | AP14: =AO14+AN14+AI14 -> 25
A15: =ROW()-3 -> 12 | B15: 1A | C15: T218EES | D15: T349EGE | E15: ABRAHAM KATINA SHIJA | F15: KOLWEZI | G15: OFFLOADED | H15: 29 | I15: 36250 | J15: 36323 | K15: AN-HDAN | L15: 45890 | M15: ESL | N15: BC Raeda | O15: 45881 | P15: 45907 | Q15: 45892 | R15: 45949 | S15: 45950 | T15: 45953 | U15: 45957 | V15: 45960 | W15: 45960 | X15: 45960 | Y15: 45965 | Z15: 45965 | AA15: 45966 | AB15: 45966 | AC15: 45968 | AD15: COMPLETED | AE15: =MAX(0,Y15-X15) -> 5 | AF15: 7 | AG15: =MAX(0,AE15-AF15) -> 0 | AH15: 200 | AI15: =MAX(0,AG15*AH15) -> 0 | AJ15: =MAX(0,AC15-AB15) -> 2 | AK15: 2 | AL15: =MAX(0,AJ15-AK15) -> 0 | AM15: 200 | AN15: =MAX(0,AL15*AM15) -> 0 | AO15: 50 | AP15: =AO15+AN15+AI15 -> 50
